Workbook

Sheet 원자료_통합
A1: resp_id | B1: 원본행 | C1: 타임스탬프 | D1: 집단 | E1: group | F1: 현장명 | G1: 성명 | H1: A-1 | I1: A-2 | J1: A-3 | K1: A-4 | L1: A-5 | M1: A-6 | N1: A-7 | O1: A-8 | P1: A-9 | Q1: B-1 | R1: B-2 | S1: B-3 | T1: B-4 | U1: B-5 | V1: B-6 | W1: B-7 | X1: B-8 | Y1: C-1 | Z1: C-2 | AA1: C-3 | AB1: C-4 | AC1: D-1 | AD1: D-2 | AE1: D-3 | AF1: D-4 | AG1: D-5 | AH1: D-6 | AI1: D-7 | AJ1: D-8 | AK1: E-1 | AL1: E-2 | AM1: E-3 | AN1: E-4 | AO1: include | AP1: exclude_reason
A2: R001 | B2: 2 | C2: 46309.439 | D2: CCTV YOLO-LLM 안전알림 도입 현장 | E2: 1 | F2: 테스트 | G2: 진정한 | H2: 발주청(공사감독·감리원 포함) | I2: 남성 | J2: 34 | K2: 6 | L2: 공사감독 | M2: 50억 원 이상∼120억 원 미만 | N2: 사무실 등에서 CCTV 화면을 직접 본다 | O2: 발생 직후 알림으로 | P2: 5분 초과∼30분 | Q2: 3 | R2: 3 | S2: 3 | T2: 3 | U2: 3 | V2: 3 | W2: 3 | X2: 3 | Y2: 3 | Z2: 3 | AA2: 3 | AB2: 3 | AC2: 3 | AD2: 3 | AE2: 3 | AF2: 3 | AG2: 3 | AH2: 3 | AI2: 3 | AJ2: 3 | AK2: 3 | AL2: 3 | AM2: 3 | AN2: 3 | AO2: 0 | AP2: 시험 응답(현장명 '테스트')
A3: R002 | B3: 3 | C3: 46309.439 | D3: CCTV YOLO-LLM 안전알림 도입 현장 | E3: 1 | F3: 없음 | G3: 윤혁 | H3: 발주청(공사감독·감리원 포함) | I3: 남성 | J3: 38 | K3: 11 | L3: 공사감독 | M3: 20억 원 미만 | N3: 알게 될 방법이 없다 | O3: 다음 순찰 때 | P3: 즉시∼5분 | Q3: 5 | R3: 5 | S3: 5 | T3: 5 | U3: 5 | V3: 5 | W3: 5 | X3: 5 | Y3: 5 | Z3: 5 | AA3: 5 | AB3: 5 | AC3: 5 | AD3: 5 | AE3: 5 | AF3: 5 | AG3: 5 | AH3: 5 | AI3: 5 | AJ3: 5 | AK3: 5 | AL3: 5 | AM3: 5 | AN3: 5 | AO3: 0 | AP3: 연구자 본인 시험 응답(현장명 '없음')
A4: R003 | B4: 4 | C4: 46309.482 | D4: CCTV YOLO-LLM 안전알림 미도입 현장 | E4: 0 | F4: 구법지구수리시설 개보수사업 | G4: 이택수 | H4: 시공사 | I4: 남성 | J4: 58 | K4: 35 | L4: 현장소장 | M4: 20억 원 이상∼50억 원 미만 | N4: 작업자나 반장의 전화·보고 | O4: 누군가 알려줄 때 | P4: 5분 초과∼30분 | Q4: 3 | R4: 3 | S4: 2 | T4: 2 | U4: 2 | V4: 3 | W4: 3 | X4: 4 | Y4: 4 | Z4: 4 | AA4: 4 | AB4: 4 | AO4: 1
A5: R004 | B5: 5 | C5: 46310.255 | D5: CCTV YOLO-LLM 안전알림 미도입 현장 | E5: 0 | F5: 신원지구 배수개선사업 토목.기계.건축공사 | G5: 김상운 | H5: 시공사 | I5: 남성 | J5: 63 | K5: 34 | L5: 현장소장 | M5: 50억 원 이상∼120억 원 미만 | N5: 작업자나 반장의 전화·보고 | O5: 누군가 알려줄 때 | P5: 5분 초과∼30분 | Q5: 4 | R5: 4 | S5: 4 | T5: 3 | U5: 3 | V5: 4 | W5: 4 | X5: 3 | Y5: 3 | Z5: 3 | AA5: 3 | AB5: 3 | AO5: 1
A6: R005 | B6: 6 | C6: 46310.615 | D6: CCTV YOLO-LLM 안전알림 도입 현장 | E6: 1 | F6: 소청 하수처리시설확충사업 | G6: 정운천 | H6: 발주청(공사감독·감리원 포함) | I6: 남성 | J6: 48 | K6: 9 | L6: 공사감독 | M6: 50억 원 이상∼120억 원 미만 | N6: 작업자나 반장의 전화·보고 | O6: 다음 순찰 때 | P6: 즉시∼5분 | Q6: 3 | R6: 4 | S6: 3 | T6: 4 | U6: 4 | V6: 4 | W6: 4 | X6: 4 | Y6: 3 | Z6: 3 | AA6: 3 | AB6: 3 | AC6: 3 | AD6: 3 | AE6: 4 | AF6: 4 | AG6: 4 | AH6: 3 | AI6: 4 | AJ6: 4 | AK6: 4 | AL6: 4 | AM6: 4 | AN6: 4 | AO6: 1
A7: R006 | B7: 7 | C7: 46315.346 | D7: CCTV YOLO-LLM 안전알림 도입 현장 | E7: 1 | H7: 시공사 | I7: 남성 | J7: 50 | K7: 25 | L7: 안전관리자 | M7: 120억 원 이상 | N7: 작업자나 반장의 전화·보고 | O7: 다음 순찰 때 | P7: 5분 초과∼30분 | Q7: 3 | R7: 3 | S7: 4 | T7: 4 | U7: 4 | V7: 4 | W7: 4 | X7: 4 | Y7: 5 | Z7: 5 | AA7: 5 | AB7: 4 | AC7: 4 | AD7: 4 | AE7: 4 | AF7: 4 | AG7: 4 | AH7: 4 | AI7: 4 | AJ7: 4 | AK7: 4 | AL7: 4 | AM7: 4 | AN7: 4 | AO7: 1
A8: R007 | B8: 8 | C8: 46315.347 | D8: CCTV YOLO-LLM 안전알림 미도입 현장 | E8: 0 | H8: 시공사 | I8: 남성 | J8: 51 | K8: 26 | L8: 안전관리자 | M8: 120억 원 이상 | N8: 작업자나 반장의 전화·보고 | O8: 누군가 알려줄 때 | P8: 즉시∼5분 | Q8: 4 | R8: 4 | S8: 4 | T8: 4 | U8: 3 | V8: 4 | W8: 4 | X8: 4 | Y8: 4 | Z8: 4 | AA8: 4 | AB8: 4 | AO8: 1
A9: R008 | B9: 9 | C9: 46315.353 | D9: CCTV YOLO-LLM 안전알림 미도입 현장 | E9: 0 | H9: 시공사 | I9: 남성 | J9: 43 | K9: 1 | L9: 현장소장 | M9: 20억 원 이상∼50억 원 미만 | N9: 작업자나 반장의 전화·보고 | O9: 누군가 알려줄 때 | P9: 즉시∼5분 | Q9: 4 | R9: 3 | S9: 3 | T9: 4 | U9: 3 | V9: 2 | W9: 3 | X9: 4 | Y9: 3 | Z9: 4 | AA9: 4 | AB9: 3 | AO9: 1
A10: R009 | B10: 10 | C10: 46315.354 | D10: CCTV YOLO-LLM 안전알림 도입 현장 | E10: 1 | H10: 발주청(공사감독·감리원 포함) | I10: 남성 | J10: 32 | K10: 2 | L10: 공사감독 | M10: 50억 원 이상∼120억 원 미만 | N10: 사무실 등에서 CCTV 화면을 직접 본다 | O10: 누군가 알려줄 때 | P10: 30분 초과∼1시간 | Q10: 5 | R10: 5 | S10: 5 | T10: 5 | U10: 5 | V10: 5 | W10: 5 | X10: 5 | Y10: 3 | Z10: 3 | AA10: 2 | AB10: 2 | AC10: 5 | AD10: 5 | AE10: 5 | AF10: 5 | AG10: 5 | AH10: 5 | AI10: 5 | AJ10: 5 | AK10: 5 | AL10: 5 | AM10: 5 | AN10: 5 | AO10: 1
A11: R010 | B11: 11 | C11: 46315.361 | D11: CCTV YOLO-LLM 안전알림 도입 현장 | E11: 1 | H11: 발주청(공사감독·감리원 포함) | I11: 남성 | J11: 32 | K11: 5 | L11: 공사감독 | M11: 20억 원 이상∼50억 원 미만 | N11: 자동 알림(문자·메신저·앱)을 받는다 | O11: 발생 직후 알림으로 | P11: 5분 초과∼30분 | Q11: 2 | R11: 3 | S11: 3 | T11: 3 | U11: 3 | V11: 3 | W11: 4 | X11: 3 | Y11: 4 | Z11: 4 | AA11: 4 | AB11: 4 | AC11: 4 | AD11: 3 | AE11: 3 | AF11: 3 | AG11: 2 | AH11: 2 | AI11: 4 | AJ11: 3 | AK11: 3 | AL11: 3 | AM11: 3 | AN11: 3 | AO11: 1
A12: R011 | B12: 12 | C12: 46315.371 | D12: CCTV YOLO-LLM 안전알림 도입 현장 | E12: 1 | H12: 발주청(공사감독·감리원 포함) | I12: 남성 | J12: 49 | K12: 1 | L12: 공사감독 | M12: 50억 원 이상∼120억 원 미만 | N12: 작업자나 반장의 전화·보고 | O12: 누군가 알려줄 때 | P12: 5분 초과∼30분 | Q12: 2 | R12: 3 | S12: 3 | T12: 2 | U12: 5 | V12: 2 | W12: 3 | X12: 3 | Y12: 2 | Z12: 2 | AA12: 2 | AB12: 2 | AC12: 4 | AD12: 4 | AE12: 4 | AF12: 4 | AG12: 3 | AH12: 3 | AI12: 4 | AJ12: 4 | AK12: 3 | AL12: 3 | AM12: 2 | AN12: 2 | AO12: 1
A13: R012 | B13: 13 | C13: 46315.409 | D13: CCTV YOLO-LLM 안전알림 도입 현장 | E13: 1 | H13: 발주청(공사감독·감리원 포함) | I13: 남성 | J13: 30 | K13: 3 | L13: 공사감독 | M13: 20억 원 이상∼50억 원 미만 | N13: 자동 알림(문자·메신저·앱)을 받는다 | O13: 누군가 알려줄 때 | P13: 5분 초과∼30분 | Q13: 4 | R13: 5 | S13: 3 | T13: 4 | U13: 4 | V13: 3 | W13: 4 | X13: 4 | Y13: 2 | Z13: 2 | AA13: 3 | AB13: 5 | AC13: 5 | AD13: 4 | AE13: 4 | AF13: 3 | AG13: 4 | AH13: 4 | AI13: 5 | AJ13: 4 | AK13: 3 | AL13: 2 | AM13: 2 | AN13: 2 | AO13: 1
A14: R013 | B14: 14 | C14: 46315.53 | D14: CCTV YOLO-LLM 안전알림 도입 현장 | E14: 1 | H14: 시공사 | I14: 남성 | J14: 65 | K14: 12 | L14: 안전관리자 | M14: 120억 원 이상 | N14: 작업자나 반장의 전화·보고 | O14: 모르고 지나가는 경우가 많다 | P14: 5분 초과∼30분 | Q14: 3 | R14: 5 | S14: 5 | T14: 5 | U14: 5 | V14: 5 | W14: 5 | X14: 5 | Y14: 5 | Z14: 5 | AA14: 5 | AB14: 5 | AC14: 5 | AD14: 5 | AE14: 5 | AF14: 5 | AG14: 5 | AH14: 5 | AI14: 5 | AJ14: 5 | AK14: 5 | AL14: 5 | AM14: 5 | AN14: 5 | AO14: 1
A15: R014 | B15: 15 | C15: 46315.53 | D15: CCTV YOLO-LLM 안전알림 도입 현장 | E15: 1 | H15: 시공사 | I15: 남성 | J15: 53 | K15: 28 | L15: 현장소장 | M15: 50억 원 이상∼120억 원 미만 | N15: 사무실 등에서 CCTV 화면을 직접 본다 | O15: 다음 순찰 때 | P15: 즉시∼5분 | Q15: 5 | R15: 5 | S15: 5 | T15: 4 | U15: 4 | V15: 4 | W15: 5 | X15: 4 | Y15: 4 | Z15: 4 | AA15: 4 | AB15: 4 | AC15: 4 | AD15: 2 | AE15: 4 | AF15: 2 | AG15: 3 | AH15: 3 | AI15: 4 | AJ15: 3 | AK15: 4 | AL15: 4 | AM15: 2 | AN15: 4 | AO15: 1
A16: R015 | B16: 16 | C16: 46315.531 | D16: CCTV YOLO-LLM 안전알림 도입 현장 | E16: 1 | H16: 시공사 | I16: 남성 | J16: 53 | K16: 23 | L16: 현장소장 | M16: 50억 원 이상∼120억 원 미만 | N16: 작업자나 반장의 전화·보고 | O16: 누군가 알려줄 때 | P16: 5분 초과∼30분 | Q16: 4 | R16: 4 | S16: 4 | T16: 3 | U16: 3 | V16: 4 | W16: 4 | X16: 4 | Y16: 3 | Z16: 3 | AA16: 5 | AB16: 4 | AC16: 3 | AD16: 3 | AE16: 3 | AF16: 3 | AG16: 3 | AH16: 3 | AI16: 4 | AJ16: 4 | AK16: 3 | AL16: 3 | AM16: 4 | AN16: 4 | AO16: 1
A17: R016 | B17: 17 | C17: 46315.532 | D17: CCTV YOLO-LLM 안전알림 미도입 현장 | E17: 0 | H17: 시공사 | I17: 남성 | J17: 52 | K17: 25 | L17: 현장소장 | M17: 50억 원 이상∼120억 원 미만 | N17: 사무실 등에서 CCTV 화면을 직접 본다 | O17: 누군가 알려줄 때 | P17: 즉시∼5분 | Q17: 4 | R17: 4 | S17: 3 | T17: 4 | U17: 4 | V17: 4 | W17: 4 | X17: 4 | Y17: 2 | Z17: 2 | AA17: 4 | AB17: 1 | AO17: 1
A18: R017 | B18: 18 | C18: 46315.534 | D18: CCTV YOLO-LLM 안전알림 도입 현장 | E18: 1 | H18: 발주청(공사감독·감리원 포함) | I18: 남성 | J18: 54 | K18: 20 | L18: 공사감독 | M18: 120억 원 이상 | N18: 자동 알림(문자·메신저·앱)을 받는다 | O18: 발생 직후 알림으로 | P18: 5분 초과∼30분 | Q18: 3 | R18: 4 | S18: 4 | T18: 4 | U18: 4 | V18: 4 | W18: 4 | X18: 4 | Y18: 2 | Z18: 2 | AA18: 2 | AB18: 2 | AC18: 3 | AD18: 4 | AE18: 4 | AF18: 4 | AG18: 3 | AH18: 3 | AI18: 4 | AJ18: 3 | AK18: 4 | AL18: 4 | AM18: 4 | AN18: 4 | AO18: 1
A19: R018 | B19: 19 | C19: 46315.535 | D19: CCTV YOLO-LLM 안전알림 미도입 현장 | E19: 0 | H19: 시공사 | I19: 남성 | J19: 28 | K19: 3 | L19: 안전관리자 | M19: 120억 원 이상 | N19: 작업자나 반장의 전화·보고 | O19: 누군가 알려줄 때 | P19: 5분 초과∼30분 | Q19: 3 | R19: 3 | S19: 2 | T19: 2 | U19: 2 | V19: 1 | W19: 2 | X19: 4 | Y19: 1 | Z19: 1 | AA19: 1 | AB19: 1 | AO19: 1
A20: R019 | B20: 20 | C20: 46315.535 | D20: CCTV YOLO-LLM 안전알림 도입 현장 | E20: 1 | H20: 발주청(공사감독·감리원 포함) | I20: 남성 | J20: 34 | K20: 2 | L20: 공사감독 | M20: 20억 원 이상∼50억 원 미만 | N20: 작업자나 반장의 전화·보고 | O20: 다음 순찰 때 | P20: 5분 초과∼30분 | Q20: 3 | R20: 4 | S20: 4 | T20: 4 | U20: 3 | V20: 3 | W20: 4 | X20: 4 | Y20: 3 | Z20: 3 | AA20: 3 | AB20: 3 | AC20: 3 | AD20: 4 | AE20: 3 | AF20: 3 | AG20: 2 | AH20: 3 | AI20: 4 | AJ20: 3 | AK20: 4 | AL20: 4 | AM20: 4 | AN20: 3 | AO20: 1
A21: R020 | B21: 21 | C21: 46315.537 | D21: CCTV YOLO-LLM 안전알림 미도입 현장 | E21: 0 | H21: 시공사 | I21: 남성 | J21: 65 | K21: 45 | L21: 현장소장 | M21: 20억 원 이상∼50억 원 미만 | N21: 현장상주 | O21: 다음 순찰 때 | P21: 즉시∼5분 | Q21: 5 | R21: 5 | S21: 5 | T21: 5 | U21: 5 | V21: 5 | W21: 5 | X21: 5 | Y21: 1 | Z21: 1 | AA21: 1 | AB21: 1 | AO21: 1
A22: R021 | B22: 22 | C22: 46315.538 | D22: CCTV YOLO-LLM 안전알림 도입 현장 | E22: 1 | H22: 시공사 | I22: 남성 | J22: 66 | K22: 33 | L22: 현장소장 | M22: 20억 원 미만 | N22: 작업자나 반장의 전화·보고 | O22: 다음 순찰 때 | P22: 즉시∼5분 | Q22: 5 | R22: 5 | S22: 4 | T22: 4 | U22: 5 | V22: 4 | W22: 5 | X22: 5 | Y22: 5 | Z22: 5 | AA22: 5 | AB22: 5 | AC22: 1 | AD22: 2 | AE22: 4 | AF22: 4 | AG22: 5 | AH22: 5 | AI22: 5 | AJ22: 5 | AK22: 5 | AL22: 5 | AM22: 5 | AN22: 5 | AO22: 1
A23: R022 | B23: 23 | C23: 46315.539 | D23: CCTV YOLO-LLM 안전알림 미도입 현장 | E23: 0 | H23: 시공사 | I23: 남성 | J23: 56 | K23: 30 | L23: 현장소장 | M23: 20억 원 이상∼50억 원 미만 | N23: 작업자나 반장의 전화·보고 | O23: 누군가 알려줄 때 | P23: 5분 초과∼30분 | Q23: 4 | R23: 5 | S23: 3 | T23: 3 | U23: 3 | V23: 3 | W23: 4 | X23: 4 | Y23: 3 | Z23: 2 | AA23: 2 | AB23: 3 | AO23: 1
A24: R023 | B24: 24 | C24: 46315.54 | D24: CCTV YOLO-LLM 안전알림 미도입 현장 | E24: 0 | H24: 시공사 | I24: 남성 | J24: 63 | K24: 33 | L24: 안전관리자 | M24: 120억 원 이상 | N24: 작업자나 반장의 전화·보고 | O24: 다음 순찰 때 | P24: 30분 초과∼1시간 | Q24: 3 | R24: 4 | S24: 2 | T24: 2 | U24: 3 | V24: 3 | W24: 3 | X24: 3 | Y24: 4 | Z24: 4 | AA24: 4 | AB24: 4 | AO24: 1
A25: R024 | B25: 25 | C25: 46315.541 | D25: CCTV YOLO-LLM 안전알림 도입 현장 | E25: 1 | H25: 시공사 | I25: 남성 | J25: 64 | K25: 1 | L25: 현장소장 | M25: 50억 원 이상∼120억 원 미만 | N25: 수시로 현장을 답사하여 확인한다 | O25: 누군가 알려줄 때 | P25: 즉시∼5분 | Q25: 5 | R25: 5 | S25: 5 | T25: 5 | U25: 5 | V25: 5 | W25: 5 | X25: 5 | Y25: 3 | Z25: 1 | AA25: 1 | AB25: 1 | AC25: 5 | AD25: 5 | AE25: 5 | AF25: 1 | AG25: 2 | AH25: 3 | AI25: 5 | AJ25: 5 | AK25: 1 | AL25: 1 | AM25: 5 | AN25: 1 | AO25: 1
A26: R025 | B26: 26 | C26: 46315.542 | D26: CCTV YOLO-LLM 안전알림 미도입 현장 | E26: 0 | H26: 시공사 | I26: 남성 | J26: 48 | K26: 25 | L26: 현장소장 | M26: 120억 원 이상 | N26: 사무실 등에서 CCTV 화면을 직접 본다 | O26: 발생 직후 알림으로 | P26: 즉시∼5분 | Q26: 5 | R26: 5 | S26: 5 | T26: 5 | U26: 5 | V26: 5 | W26: 5 | X26: 5 | Y26: 2 | Z26: 4 | AA26: 2 | AB26: 2 | AO26: 1
A27: R026 | B27: 27 | C27: 46315.544 | D27: CCTV YOLO-LLM 안전알림 도입 현장 | E27: 1 | H27: 발주청(공사감독·감리원 포함) | I27: 남성 | J27: 45 | K27: 12 | L27: 공사감독 | M27: 50억 원 이상∼120억 원 미만 | N27: 사무실 등에서 CCTV 화면을 직접 본다 | O27: 누군가 알려줄 때 | P27: 5분 초과∼30분 | Q27: 5 | R27: 5 | S27: 5 | T27: 5 | U27: 5 | V27: 5 | W27: 5 | X27: 5 | Y27: 2 | Z27: 2 | AA27: 2 | AB27: 5 | AC27: 5 | AD27: 5 | AE27: 5 | AF27: 5 | AG27: 5 | AH27: 5 | AI27: 5 | AJ27: 5 | AK27: 5 | AL27: 5 | AM27: 5 | AN27: 5 | AO27: 1
A28: R027 | B28: 28 | C28: 46315.544 | D28: CCTV YOLO-LLM 안전알림 미도입 현장 | E28: 0 | H28: 발주청(공사감독·감리원 포함) | I28: 남성 | J28: 39 | K28: 15 | L28: 공사감독 | M28: 20억 원 미만 | N28: 알게 될 방법이 없다 | O28: 누군가 알려줄 때 | P28: 5분 초과∼30분 | Q28: 2 | R28: 3 | S28: 1 | T28: 2 | U28: 2 | V28: 1 | W28: 2 | X28: 2 | Y28: 5 | Z28: 4 | AA28: 4 | AB28: 4 | AO28: 1
A29: R028 | B29: 29 | C29: 46315.547 | D29: CCTV YOLO-LLM 안전알림 도입 현장 | E29: 1 | H29: 시공사 | I29: 남성 | J29: 37 | K29: 11 | L29: 안전관리자 | M29: 120억 원 이상 | N29: 자동 알림(문자·메신저·앱)을 받는다 | O29: 다음 순찰 때 | P29: 5분 초과∼30분 | Q29: 4 | R29: 4 | S29: 4 | T29: 3 | U29: 3 | V29: 3 | W29: 5 | X29: 5 | Y29: 3 | Z29: 3 | AA29: 4 | AB29: 5 | AC29: 3 | AD29: 2 | AE29: 3 | AF29: 2 | AG29: 3 | AH29: 3 | AI29: 2 | AJ29: 3 | AK29: 3 | AL29: 3 | AM29: 4 | AN29: 3 | AO29: 1
A30: R029 | B30: 30 | C30: 46315.548 | D30: CCTV YOLO-LLM 안전알림 미도입 현장 | E30: 0 | H30: 시공사 | I30: 남성 | J30: 32 | K30: 5 | L30: 안전관리자 | M30: 120억 원 이상 | N30: 사무실 등에서 CCTV 화면을 직접 본다 | O30: 누군가 알려줄 때 | P30: 즉시∼5분 | Q30: 4 | R30: 4 | S30: 3 | T30: 4 | U30: 4 | V30: 5 | W30: 5 | X30: 5 | Y30: 4 | Z30: 4 | AA30: 3 | AB30: 4 | AO30: 1
A31: R030 | B31: 31 | C31: 46315.548 | D31: CCTV YOLO-LLM 안전알림 미도입 현장 | E31: 0 | H31: 발주청(공사감독·감리원 포함) | I31: 여성 | J31: 24 | K31: 1 | L31: . | M31: 20억 원 이상∼50억 원 미만 | N31: 작업자나 반장의 전화·보고 | O31: 누군가 알려줄 때 | P31: 5분 초과∼30분 | Q31: 4 | R31: 4 | S31: 4 | T31: 4 | U31: 4 | V31: 4 | W31: 4 | X31: 4 | Y31: 4 | Z31: 4 | AA31: 4 | AB31: 4 | AO31: 1
A32: R031 | B32: 32 | C32: 46315.548 | D32: CCTV YOLO-LLM 안전알림 도입 현장 | E32: 1 | H32: 발주청(공사감독·감리원 포함) | I32: 남성 | J32: 30 | K32: 4 | L32: 공사감독 | M32: 50억 원 이상∼120억 원 미만 | N32: 작업자나 반장의 전화·보고 | O32: 누군가 알려줄 때 | P32: 30분 초과∼1시간 | Q32: 4 | R32: 4 | S32: 4 | T32: 4 | U32: 4 | V32: 4 | W32: 4 | X32: 4 | Y32: 2 | Z32: 2 | AA32: 2 | AB32: 2 | AC32: 4 | AD32: 4 | AE32: 4 | AF32: 4 | AG32: 2 | AH32: 2 | AI32: 4 | AJ32: 3 | AK32: 1 | AL32: 2 | AM32: 5 | AN32: 3 | AO32: 1
A33: R032 | B33: 33 | C33: 46315.549 | D33: CCTV YOLO-LLM 안전알림 미도입 현장 | E33: 0 | H33: 발주청(공사감독·감리원 포함) | I33: 남성 | J33: 52 | K33: 28 | L33: 공사감독 | M33: 120억 원 이상 | N33: 사무실 등에서 CCTV 화면을 직접 본다 | O33: 모르고 지나가는 경우가 많다 | P33: 30분 초과∼1시간 | Q33: 3 | R33: 3 | S33: 3 | T33: 3 | U33: 3 | V33: 3 | W33: 4 | X33: 3 | Y33: 5 | Z33: 4 | AA33: 5 | AB33: 5 | AO33: 1
A34: R033 | B34: 34 | C34: 46315.55 | D34: CCTV YOLO-LLM 안전알림 도입 현장 | E34: 1 | H34: 시공사 | I34: 남성 | J34: 51 | K34: 30 | L34: 현장소장 | M34: 50억 원 이상∼120억 원 미만 | N34: 현장상주 미상주시 대체직원 상주 | O34: 다음 순찰 때 | P34: 즉시∼5분 | Q34: 4 | R34: 4 | S34: 4 | T34: 4 | U34: 4 | V34: 4 | W34: 4 | X34: 4 | Y34: 4 | Z34: 3 | AA34: 4 | AB34: 3 | AC34: 4 | AD34: 4 | AE34: 4 | AF34: 4 | AG34: 3 | AH34: 3 | AI34: 3 | AJ34: 3 | AK34: 3 | AL34: 3 | AM34: 4 | AN34: 3 | AO34: 1
A35: R034 | B35: 35 | C35: 46315.551 | D35: CCTV YOLO-LLM 안전알림 도입 현장 | E35: 1 | H35: 시공사 | I35: 남성 | J35: 58 | K35: 6 | L35: 안전관리자 | M35: 50억 원 이상∼120억 원 미만 | N35: 자동 알림(문자·메신저·앱)을 받는다 | O35: 발생 직후 알림으로 | P35: 즉시∼5분 | Q35: 4 | R35: 4 | S35: 4 | T35: 4 | U35: 4 | V35: 4 | W35: 4 | X35: 4 | Y35: 2 | Z35: 2 | AA35: 2 | AB35: 2 | AC35: 3 | AD35: 4 | AE35: 4 | AF35: 3 | AG35: 3 | AH35: 3 | AI35: 4 | AJ35: 3 | AK35: 4 | AL35: 4 | AM35: 4 | AN35: 4 | AO35: 1
A36: R035 | B36: 36 | C36: 46315.554 | D36: CCTV YOLO-LLM 안전알림 도입 현장 | E36: 1 | H36: 시공사 | I36: 남성 | J36: 46 | K36: 20 | L36: 현장소장 | M36: 120억 원 이상 | N36: 작업자나 반장의 전화·보고 | O36: 누군가 알려줄 때 | P36: 5분 초과∼30분 | Q36: 4 | R36: 4 | S36: 3 | T36: 3 | U36: 3 | V36: 4 | W36: 4 | X36: 4 | Y36: 4 | Z36: 4 | AA36: 4 | AB36: 4 | AC36: 3 | AD36: 3 | AE36: 4 | AF36: 3 | AG36: 3 | AH36: 4 | AI36: 5 | AJ36: 3 | AK36: 1 | AL36: 2 | AM36: 4 | AN36: 5 | AO36: 1
A37: R036 | B37: 37 | C37: 46315.56 | D37: CCTV YOLO-LLM 안전알림 미도입 현장 | E37: 0 | H37: 발주청(공사감독·감리원 포함) | I37: 남성 | J37: 60 | K37: 36 | L37: 공사감독 | M37: 120억 원 이상 | N37: 작업자나 반장의 전화·보고 | O37: 누군가 알려줄 때 | P37: 5분 초과∼30분 | Q37: 3 | R37: 3 | S37: 2 | T37: 3 | U37: 2 | V37: 2 | W37: 3 | X37: 3 | Y37: 2 | Z37: 2 | AA37: 3 | AB37: 2 | AO37: 1
A38: R037 | B38: 38 | C38: 46315.561 | D38: CCTV YOLO-LLM 안전알림 도입 현장 | E38: 1 | H38: 발주청(공사감독·감리원 포함) | I38: 남성 | J38: 56 | K38: 30 | L38: 사업관리(부장) | M38: 50억 원 이상∼120억 원 미만 | N38: 자동 알림(문자·메신저·앱)을 받는다 | O38: 발생 직후 알림으로 | P38: 즉시∼5분 | Q38: 3 | R38: 5 | S38: 3 | T38: 5 | U38: 4 | V38: 3 | W38: 5 | X38: 5 | Y38: 2 | Z38: 2 | AA38: 2 | AB38: 4 | AC38: 4 | AD38: 4 | AE38: 4 | AF38: 4 | AG38: 4 | AH38: 3 | AI38: 5 | AJ38: 5 | AK38: 5 | AL38: 5 | AM38: 5 | AN38: 5 | AO38: 1
A39: R038 | B39: 39 | C39: 46315.567 | D39: CCTV YOLO-LLM 안전알림 미도입 현장 | E39: 0 | H39: 시공사 | I39: 남성 | J39: 57 | K39: 32 | L39: 현장소장 | M39: 20억 원 미만 | N39: 현장상주 직접확인 | O39: 누군가 알려줄 때 | P39: 즉시∼5분 | Q39: 5 | R39: 5 | S39: 5 | T39: 5 | U39: 5 | V39: 5 | W39: 5 | X39: 5 | Y39: 1 | Z39: 1 | AA39: 1 | AB39: 1 | AO39: 1
A40: R039 | B40: 40 | C40: 46315.567 | D40: CCTV YOLO-LLM 안전알림 미도입 현장 | E40: 0 | H40: 발주청(공사감독·감리원 포함) | I40: 남성 | J40: 55 | K40: 25 | L40: 기술사사무소 | M40: 20억 원 미만 | N40: 알게 될 방법이 없다 | O40: 누군가 알려줄 때 | P40: 1시간 초과 또는 다음 순찰 때 | Q40: 3 | R40: 4 | S40: 2 | T40: 2 | U40: 2 | V40: 3 | W40: 3 | X40: 3 | Y40: 4 | Z40: 4 | AA40: 4 | AB40: 5 | AO40: 1
...

Sheet README
A1: 설문 응답 정리본
A3: 목적 | B3: Google Forms 응답 원본(도입/미도입 분기로 열이 두 묶음)을 한 열 세트로 합치고, 숫자 코딩·파생 척도·빈도/기술통계를 정리한 작업본.
A4: 원본 경로 | B4: 01.docs/설문결과/중소규모 건설현장을 위한 YOLO-LLM 안전관제 시스템 개발 및 실증 연구(응답).xlsx
A5: 원본 SHA256 | B5: e81a9f6fb5e2557024bdade531bd467a6701944a6d458699334ce94d34f68027 (읽기 전용 — 이 파일 생성 전후 불변 확인)
A6: 생성 시각 | B6: 2026-10-24 09:03 (Asia/Seoul)
A7: 생성 스크립트 | B7: tools/survey_analysis/build_workbook.py (코딩 규칙: tools/survey_analysis/coding.py)
A8: 코딩 규칙 근거 | B8: 03.plan/261024_0850_설문응답_정리_분석_원고반영_계획.md 0.3·0.4절, 문항 전문 01.docs/부록1_설문지_양식.md, 변수 역할 01.docs/04_연구설계.md <표 4-3>
A9: 응답 수 | B9: 전체 73건(도입 34, 미도입 39), 분석 포함 include=1 71건(도입 32, 미도입 39). 시험 응답 2건 제외.
A10: 집단 기준 | B10: group은 첫 질문의 자기보고 분기값이다. 원고 원칙상 분석용 집단은 조사 명부로 판정하므로 이 값은 '명부 대조 전 자기보고 기준'이다.
A11: jamovi 투입 | B11: 분석자료 시트 또는 01.docs/설문결과/analysis/coded_data.csv(UTF-8 BOM)를 사용하고 include=1로 필터한다. 성명·현장명은 들어 있지 않다.
A12: 값 전용 시트 | B12: 분석자료는 설계상 값 전용(수식 없음)이다. 파생값은 Python으로 계산했으며 코딩자료의 수식과 같은 규칙이다(검증: 전 셀 일치).
A13: 색 범례 | B13: 파란 글자 = 입력값(원문·코딩값·값 전용 자료), 검은 글자 = 수식, 노란 채움 = D함수 조건 범위(수정 금지).
A14: 자료 특성 요약 | B14: ① 도입 집단 전원 남성(여성은 미도입에만) ② 소속–역할 중복(발주청≈공사감독)으로 설계행렬 순위 결함 가능 ③ 현장명·성명이 5건에만 있어 중복 확인은 타임스탬프·응답 벡터로만 가능(완전 동일 벡터 0건) ④ 집단은 명부 대조 전 자기보고 ⑤ 도입 집단 중 시스템 경로 작동(sys_path=1)은 소수 — 상세는 검토메모.
... A24: 검토메모 | B24: 자료 특성·이상값·결측·중복 의심·제외·검증 결과. 각 건의 resp_id·원본 행·내용·처리·상태.

Sheet 코딩자료
A1: resp_id | B1: 원본행 | C1: group | D1: A1_소속 | E1: A2_성별 | F1: A3_나이 | G1: A4_경력 | H1: A5_역할 | I1: A5_기타텍스트 | J1: A6_총공사비 | K1: A7_인지경로 | L1: A7_기타텍스트 | M1: A8_인지시점 | N1: A9_전달소요 | O1: B1 | P1: B2 | Q1: B3 | R1: B4 | S1: B5 | T1: B6 | U1: B7 | V1: B8 | W1: C1 | X1: C2 | Y1: C3 | Z1: C4 | AA1: D1 | AB1: D2 | AC1: D3 | AD1: D4 | AE1: D5 | AF1: D6 | AG1: D7 | AH1: D8 | AI1: E1 | AJ1: E2 | AK1: E3 | AL1: E4 | AM1: Y_total | AN1: Y1_조기인지 | AO1: Y2_대응신속성 | AP1: Y3_원격파악 | AQ1: Y4_순찰부담경감 | AR1: Y5_위험통제력 | AS1: W_예산제약 | AT1: D_sub1_인프라범용성 | AU1: D_sub2_탐지제어안정성 | AV1: D_sub3_오탐필터링 | AW1: D_sub4_알림전파즉각성 | AX1: D_total | AY1: E_total | AZ1: sys_path | BA1: include | BB1: exclude_reason
A2: R001 | B2: 2 | C2: 1 | D2: 2 | E2: 1 | F2: 34 | G2: 6 | H2: 1 | J2: 3 | K2: 3 | M2: 3 | N2: 2 | O2: 3 | P2: 3 | Q2: 3 | R2: 3 | S2: 3 | T2: 3 | U2: 3 | V2: 3 | W2: 3 | X2: 3 | Y2: 3 | Z2: 3 | AA2: 3 | AB2: 3 | AC2: 3 | AD2: 3 | AE2: 3 | AF2: 3 | AG2: 3 | AH2: 3 | AI2: 3 | AJ2: 3 | AK2: 3 | AL2: 3 | AM2: =IF(COUNT(O2:V2)<8,"",AVERAGE(O2:V2)) | AN2: =IF(COUNT(O2:O2)<1,"",AVERAGE(O2:O2)) | AO2: =IF(COUNT(P2:P2)<1,"",AVERAGE(P2:P2)) | AP2: =IF(COUNT(Q2:R2)<2,"",AVERAGE(Q2:R2)) | AQ2: =IF(COUNT(S2:T2)<2,"",AVERAGE(S2:T2)) | AR2: =IF(COUNT(U2:V2)<2,"",AVERAGE(U2:V2)) | AS2: =IF(COUNT(W2:Z2)<4,"",AVERAGE(W2:Z2)) | AT2: =IF($C2<>1,"",IF(COUNT(AA2:AB2)<2,"",AVERAGE(AA2:AB2))) | AU2: =IF($C2<>1,"",IF(COUNT(AC2:AD2)<2,"",AVERAGE(AC2:AD2))) | AV2: =IF($C2<>1,"",IF(COUNT(AE2:AF2)<2,"",AVERAGE(AE2:AF2))) | AW2: =IF($C2<>1,"",IF(COUNT(AG2:AH2)<2,"",AVERAGE(AG2:AH2))) | AX2: =IF($C2<>1,"",IF(COUNT(AA2:AH2)<8,"",AVERAGE(AA2:AH2))) | AY2: =IF($C2<>1,"",IF(COUNT(AI2:AL2)<4,"",AVERAGE(AI2:AL2))) | AZ2: =IF($C2<>1,"",IF(OR(K2="",M2=""),"",IF(AND(OR(K2=3,K2=4),M2=3),1,0))) | BA2: 0 | BB2: 시험 응답(현장명 '테스트')
A3: R002 | B3: 3 | C3: 1 | D3: 2 | E3: 1 | F3: 38 | G3: 11 | H3: 1 | J3: 1 | K3: 1 | M3: 1 | N3: 1 | O3: 5 | P3: 5 | Q3: 5 | R3: 5 | S3: 5 | T3: 5 | U3: 5 | V3: 5 | W3: 5 | X3: 5 | Y3: 5 | Z3: 5 | AA3: 5 | AB3: 5 | AC3: 5 | AD3: 5 | AE3: 5 | AF3: 5 | AG3: 5 | AH3: 5 | AI3: 5 | AJ3: 5 | AK3: 5 | AL3: 5 | AM3: =IF(COUNT(O3:V3)<8,"",AVERAGE(O3:V3)) | AN3: =IF(COUNT(O3:O3)<1,"",AVERAGE(O3:O3)) | AO3: =IF(COUNT(P3:P3)<1,"",AVERAGE(P3:P3)) | AP3: =IF(COUNT(Q3:R3)<2,"",AVERAGE(Q3:R3)) | AQ3: =IF(COUNT(S3:T3)<2,"",AVERAGE(S3:T3)) | AR3: =IF(COUNT(U3:V3)<2,"",AVERAGE(U3:V3)) | AS3: =IF(COUNT(W3:Z3)<4,"",AVERAGE(W3:Z3)) | AT3: =IF($C3<>1,"",IF(COUNT(AA3:AB3)<2,"",AVERAGE(AA3:AB3))) | AU3: =IF($C3<>1,"",IF(COUNT(AC3:AD3)<2,"",AVERAGE(AC3:AD3))) | AV3: =IF($C3<>1,"",IF(COUNT(AE3:AF3)<2,"",AVERAGE(AE3:AF3))) | AW3: =IF($C3<>1,"",IF(COUNT(AG3:AH3)<2,"",AVERAGE(AG3:AH3))) | AX3: =IF($C3<>1,"",IF(COUNT(AA3:AH3)<8,"",AVERAGE(AA3:AH3))) | AY3: =IF($C3<>1,"",IF(COUNT(AI3:AL3)<4,"",AVERAGE(AI3:AL3))) | AZ3: =IF($C3<>1,"",IF(OR(K3="",M3=""),"",IF(AND(OR(K3=3,K3=4),M3=3),1,0))) | BA3: 0 | BB3: 연구자 본인 시험 응답(현장명 '없음')
A4: R003 | B4: 4 | C4: 0 | D4: 1 | E4: 1 | F4: 58 | G4: 35 | H4: 3 | J4: 2 | K4: 2 | M4: 2 | N4: 2 | O4: 3 | P4: 3 | Q4: 2 | R4: 2 | S4: 2 | T4: 3 | U4: 3 | V4: 4 | W4: 4 | X4: 4 | Y4: 4 | Z4: 4 | AM4: =IF(COUNT(O4:V4)<8,"",AVERAGE(O4:V4)) | AN4: =IF(COUNT(O4:O4)<1,"",AVERAGE(O4:O4)) | AO4: =IF(COUNT(P4:P4)<1,"",AVERAGE(P4:P4)) | AP4: =IF(COUNT(Q4:R4)<2,"",AVERAGE(Q4:R4)) | AQ4: =IF(COUNT(S4:T4)<2,"",AVERAGE(S4:T4)) | AR4: =IF(COUNT(U4:V4)<2,"",AVERAGE(U4:V4)) | AS4: =IF(COUNT(W4:Z4)<4,"",AVERAGE(W4:Z4)) | AT4: =IF($C4<>1,"",IF(COUNT(AA4:AB4)<2,"",AVERAGE(AA4:AB4))) | AU4: =IF($C4<>1,"",IF(COUNT(AC4:AD4)<2,"",AVERAGE(AC4:AD4))) | AV4: =IF($C4<>1,"",IF(COUNT(AE4:AF4)<2,"",AVERAGE(AE4:AF4))) | AW4: =IF($C4<>1,"",IF(COUNT(AG4:AH4)<2,"",AVERAGE(AG4:AH4))) | AX4: =IF($C4<>1,"",IF(COUNT(AA4:AH4)<8,"",AVERAGE(AA4:AH4))) | AY4: =IF($C4<>1,"",IF(COUNT(AI4:AL4)<4,"",AVERAGE(AI4:AL4))) | AZ4: =IF($C4<>1,"",IF(OR(K4="",M4=""),"",IF(AND(OR(K4=3,K4=4),M4=3),1,0))) | BA4: 1
A5: R004 | B5: 5 | C5: 0 | D5: 1 | E5: 1 | F5: 63 | G5: 34 | H5: 3 | J5: 3 | K5: 2 | M5: 2 | N5: 2 | O5: 4 | P5: 4 | Q5: 4 | R5: 3 | S5: 3 | T5: 4 | U5: 4 | V5: 3 | W5: 3 | X5: 3 | Y5: 3 | Z5: 3 | AM5: =IF(COUNT(O5:V5)<8,"",AVERAGE(O5:V5)) | AN5: =IF(COUNT(O5:O5)<1,"",AVERAGE(O5:O5)) | AO5: =IF(COUNT(P5:P5)<1,"",AVERAGE(P5:P5)) | AP5: =IF(COUNT(Q5:R5)<2,"",AVERAGE(Q5:R5)) | AQ5: =IF(COUNT(S5:T5)<2,"",AVERAGE(S5:T5)) | AR5: =IF(COUNT(U5:V5)<2,"",AVERAGE(U5:V5)) | AS5: =IF(COUNT(W5:Z5)<4,"",AVERAGE(W5:Z5)) | AT5: =IF($C5<>1,"",IF(COUNT(AA5:AB5)<2,"",AVERAGE(AA5:AB5))) | AU5: =IF($C5<>1,"",IF(COUNT(AC5:AD5)<2,"",AVERAGE(AC5:AD5))) | AV5: =IF($C5<>1,"",IF(COUNT(AE5:AF5)<2,"",AVERAGE(AE5:AF5))) | AW5: =IF($C5<>1,"",IF(COUNT(AG5:AH5)<2,"",AVERAGE(AG5:AH5))) | AX5: =IF($C5<>1,"",IF(COUNT(AA5:AH5)<8,"",AVERAGE(AA5:AH5))) | AY5: =IF($C5<>1,"",IF(COUNT(AI5:AL5)<4,"",AVERAGE(AI5:AL5))) | AZ5: =IF($C5<>1,"",IF(OR(K5="",M5=""),"",IF(AND(OR(K5=3,K5=4),M5=3),1,0))) | BA5: 1
A6: R005 | B6: 6 | C6: 1 | D6: 2 | E6: 1 | F6: 48 | G6: 9 | H6: 1 | J6: 3 | K6: 2 | M6: 1 | N6: 1 | O6: 3 | P6: 4 | Q6: 3 | R6: 4 | S6: 4 | T6: 4 | U6: 4 | V6: 4 | W6: 3 | X6: 3 | Y6: 3 | Z6: 3 | AA6: 3 | AB6: 3 | AC6: 4 | AD6: 4 | AE6: 4 | AF6: 3 | AG6: 4 | AH6: 4 | AI6: 4 | AJ6: 4 | AK6: 4 | AL6: 4 | AM6: =IF(COUNT(O6:V6)<8,"",AVERAGE(O6:V6)) | AN6: =IF(COUNT(O6:O6)<1,"",AVERAGE(O6:O6)) | AO6: =IF(COUNT(P6:P6)<1,"",AVERAGE(P6:P6)) | AP6: =IF(COUNT(Q6:R6)<2,"",AVERAGE(Q6:R6)) | AQ6: =IF(COUNT(S6:T6)<2,"",AVERAGE(S6:T6)) | AR6: =IF(COUNT(U6:V6)<2,"",AVERAGE(U6:V6)) | AS6: =IF(COUNT(W6:Z6)<4,"",AVERAGE(W6:Z6)) | AT6: =IF($C6<>1,"",IF(COUNT(AA6:AB6)<2,"",AVERAGE(AA6:AB6))) | AU6: =IF($C6<>1,"",IF(COUNT(AC6:AD6)<2,"",AVERAGE(AC6:AD6))) | AV6: =IF($C6<>1,"",IF(COUNT(AE6:AF6)<2,"",AVERAGE(AE6:AF6))) | AW6: =IF($C6<>1,"",IF(COUNT(AG6:AH6)<2,"",AVERAGE(AG6:AH6))) | AX6: =IF($C6<>1,"",IF(COUNT(AA6:AH6)<8,"",AVERAGE(AA6:AH6))) | AY6: =IF($C6<>1,"",IF(COUNT(AI6:AL6)<4,"",AVERAGE(AI6:AL6))) | AZ6: =IF($C6<>1,"",IF(OR(K6="",M6=""),"",IF(AND(OR(K6=3,K6=4),M6=3),1,0))) | BA6: 1
A7: R006 | B7: 7 | C7: 1 | D7: 1 | E7: 1 | F7: 50 | G7: 25 | H7: 2 | J7: 4 | K7: 2 | M7: 1 | N7: 2 | O7: 3 | P7: 3 | Q7: 4 | R7: 4 | S7: 4 | T7: 4 | U7: 4 | V7: 4 | W7: 5 | X7: 5 | Y7: 5 | Z7: 4 | AA7: 4 | AB7: 4 | AC7: 4 | AD7: 4 | AE7: 4 | AF7: 4 | AG7: 4 | AH7: 4 | AI7: 4 | AJ7: 4 | AK7: 4 | AL7: 4 | AM7: =IF(COUNT(O7:V7)<8,"",AVERAGE(O7:V7)) | AN7: =IF(COUNT(O7:O7)<1,"",AVERAGE(O7:O7)) | AO7: =IF(COUNT(P7:P7)<1,"",AVERAGE(P7:P7)) | AP7: =IF(COUNT(Q7:R7)<2,"",AVERAGE(Q7:R7)) | AQ7: =IF(COUNT(S7:T7)<2,"",AVERAGE(S7:T7)) | AR7: =IF(COUNT(U7:V7)<2,"",AVERAGE(U7:V7)) | AS7: =IF(COUNT(W7:Z7)<4,"",AVERAGE(W7:Z7)) | AT7: =IF($C7<>1,"",IF(COUNT(AA7:AB7)<2,"",AVERAGE(AA7:AB7))) | AU7: =IF($C7<>1,"",IF(COUNT(AC7:AD7)<2,"",AVERAGE(AC7:AD7))) | AV7: =IF($C7<>1,"",IF(COUNT(AE7:AF7)<2,"",AVERAGE(AE7:AF7))) | AW7: =IF($C7<>1,"",IF(COUNT(AG7:AH7)<2,"",AVERAGE(AG7:AH7))) | AX7: =IF($C7<>1,"",IF(COUNT(AA7:AH7)<8,"",AVERAGE(AA7:AH7))) | AY7: =IF($C7<>1,"",IF(COUNT(AI7:AL7)<4,"",AVERAGE(AI7:AL7))) | AZ7: =IF($C7<>1,"",IF(OR(K7="",M7=""),"",IF(AND(OR(K7=3,K7=4),M7=3),1,0))) | BA7: 1
A8: R007 | B8: 8 | C8: 0 | D8: 1 | E8: 1 | F8: 51 | G8: 26 | H8: 2 | J8: 4 | K8: 2 | M8: 2 | N8: 1 | O8: 4 | P8: 4 | Q8: 4 | R8: 4 | S8: 3 | T8: 4 | U8: 4 | V8: 4 | W8: 4 | X8: 4 | Y8: 4 | Z8: 4 | AM8: =IF(COUNT(O8:V8)<8,"",AVERAGE(O8:V8)) | AN8: =IF(COUNT(O8:O8)<1,"",AVERAGE(O8:O8)) | AO8: =IF(COUNT(P8:P8)<1,"",AVERAGE(P8:P8)) | AP8: =IF(COUNT(Q8:R8)<2,"",AVERAGE(Q8:R8)) | AQ8: =IF(COUNT(S8:T8)<2,"",AVERAGE(S8:T8)) | AR8: =IF(COUNT(U8:V8)<2,"",AVERAGE(U8:V8)) | AS8: =IF(COUNT(W8:Z8)<4,"",AVERAGE(W8:Z8)) | AT8: =IF($C8<>1,"",IF(COUNT(AA8:AB8)<2,"",AVERAGE(AA8:AB8))) | AU8: =IF($C8<>1,"",IF(COUNT(AC8:AD8)<2,"",AVERAGE(AC8:AD8))) | AV8: =IF($C8<>1,"",IF(COUNT(AE8:AF8)<2,"",AVERAGE(AE8:AF8))) | AW8: =IF($C8<>1,"",IF(COUNT(AG8:AH8)<2,"",AVERAGE(AG8:AH8))) | AX8: =IF($C8<>1,"",IF(COUNT(AA8:AH8)<8,"",AVERAGE(AA8:AH8))) | AY8: =IF($C8<>1,"",IF(COUNT(AI8:AL8)<4,"",AVERAGE(AI8:AL8))) | AZ8: =IF($C8<>1,"",IF(OR(K8="",M8=""),"",IF(AND(OR(K8=3,K8=4),M8=3),1,0))) | BA8: 1
A9: R008 | B9: 9 | C9: 0 | D9: 1 | E9: 1 | F9: 43 | G9: 1 | H9: 3 | J9: 2 | K9: 2 | M9: 2 | N9: 1 | O9: 4 | P9: 3 | Q9: 3 | R9: 4 | S9: 3 | T9: 2 | U9: 3 | V9: 4 | W9: 3 | X9: 4 | Y9: 4 | Z9: 3 | AM9: =IF(COUNT(O9:V9)<8,"",AVERAGE(O9:V9)) | AN9: =IF(COUNT(O9:O9)<1,"",AVERAGE(O9:O9)) | AO9: =IF(COUNT(P9:P9)<1,"",AVERAGE(P9:P9)) | AP9: =IF(COUNT(Q9:R9)<2,"",AVERAGE(Q9:R9)) | AQ9: =IF(COUNT(S9:T9)<2,"",AVERAGE(S9:T9)) | AR9: =IF(COUNT(U9:V9)<2,"",AVERAGE(U9:V9)) | AS9: =IF(COUNT(W9:Z9)<4,"",AVERAGE(W9:Z9)) | AT9: =IF($C9<>1,"",IF(COUNT(AA9:AB9)<2,"",AVERAGE(AA9:AB9))) | AU9: =IF($C9<>1,"",IF(COUNT(AC9:AD9)<2,"",AVERAGE(AC9:AD9))) | AV9: =IF($C9<>1,"",IF(COUNT(AE9:AF9)<2,"",AVERAGE(AE9:AF9))) | AW9: =IF($C9<>1,"",IF(COUNT(AG9:AH9)<2,"",AVERAGE(AG9:AH9))) | AX9: =IF($C9<>1,"",IF(COUNT(AA9:AH9)<8,"",AVERAGE(AA9:AH9))) | AY9: =IF($C9<>1,"",IF(COUNT(AI9:AL9)<4,"",AVERAGE(AI9:AL9))) | AZ9: =IF($C9<>1,"",IF(OR(K9="",M9=""),"",IF(AND(OR(K9=3,K9=4),M9=3),1,0))) | BA9: 1
A10: R009 | B10: 10 | C10: 1 | D10: 2 | E10: 1 | F10: 32 | G10: 2 | H10: 1 | J10: 3 | K10: 3 | M10: 2 | N10: 3 | O10: 5 | P10: 5 | Q10: 5 | R10: 5 | S10: 5 | T10: 5 | U10: 5 | V10: 5 | W10: 3 | X10: 3 | Y10: 2 | Z10: 2 | AA10: 5 | AB10: 5 | AC10: 5 | AD10: 5 | AE10: 5 | AF10: 5 | AG10: 5 | AH10: 5 | AI10: 5 | AJ10: 5 | AK10: 5 | AL10: 5 | AM10: =IF(COUNT(O10:V10)<8,"",AVERAGE(O10:V10)) | AN10: =IF(COUNT(O10:O10)<1,"",AVERAGE(O10:O10)) | AO10: =IF(COUNT(P10:P10)<1,"",AVERAGE(P10:P10)) | AP10: =IF(COUNT(Q10:R10)<2,"",AVERAGE(Q10:R10)) | AQ10: =IF(COUNT(S10:T10)<2,"",AVERAGE(S10:T10)) | AR10: =IF(COUNT(U10:V10)<2,"",AVERAGE(U10:V10)) | AS10: =IF(COUNT(W10:Z10)<4,"",AVERAGE(W10:Z10)) | AT10: =IF($C10<>1,"",IF(COUNT(AA10:AB10)<2,"",AVERAGE(AA10:AB10))) | AU10: =IF($C10<>1,"",IF(COUNT(AC10:AD10)<2,"",AVERAGE(AC10:AD10))) | AV10: =IF($C10<>1,"",IF(COUNT(AE10:AF10)<2,"",AVERAGE(AE10:AF10))) | AW10: =IF($C10<>1,"",IF(COUNT(AG10:AH10)<2,"",AVERAGE(AG10:AH10))) | AX10: =IF($C10<>1,"",IF(COUNT(AA10:AH10)<8,"",AVERAGE(AA10:AH10))) | AY10: =IF($C10<>1,"",IF(COUNT(AI10:AL10)<4,"",AVERAGE(AI10:AL10))) | AZ10: =IF($C10<>1,"",IF(OR(K10="",M10=""),"",IF(AND(OR(K10=3,K10=4),M10=3),1,0))) | BA10: 1
A11: R010 | B11: 11 | C11: 1 | D11: 2 | E11: 1 | F11: 32 | G11: 5 | H11: 1 | J11: 2 | K11: 4 | M11: 3 | N11: 2 | O11: 2 | P11: 3 | Q11: 3 | R11: 3 | S11: 3 | T11: 3 | U11: 4 | V11: 3 | W11: 4 | X11: 4 | Y11: 4 | Z11: 4 | AA11: 4 | AB11: 3 | AC11: 3 | AD11: 3 | AE11: 2 | AF11: 2 | AG11: 4 | AH11: 3 | AI11: 3 | AJ11: 3 | AK11: 3 | AL11: 3 | AM11: =IF(COUNT(O11:V11)<8,"",AVERAGE(O11:V11)) | AN11: =IF(COUNT(O11:O11)<1,"",AVERAGE(O11:O11)) | AO11: =IF(COUNT(P11:P11)<1,"",AVERAGE(P11:P11)) | AP11: =IF(COUNT(Q11:R11)<2,"",AVERAGE(Q11:R11)) | AQ11: =IF(COUNT(S11:T11)<2,"",AVERAGE(S11:T11)) | AR11: =IF(COUNT(U11:V11)<2,"",AVERAGE(U11:V11)) | AS11: =IF(COUNT(W11:Z11)<4,"",AVERAGE(W11:Z11)) | AT11: =IF($C11<>1,"",IF(COUNT(AA11:AB11)<2,"",AVERAGE(AA11:AB11))) | AU11: =IF($C11<>1,"",IF(COUNT(AC11:AD11)<2,"",AVERAGE(AC11:AD11))) | AV11: =IF($C11<>1,"",IF(COUNT(AE11:AF11)<2,"",AVERAGE(AE11:AF11))) | AW11: =IF($C11<>1,"",IF(COUNT(AG11:AH11)<2,"",AVERAGE(AG11:AH11))) | AX11: =IF($C11<>1,"",IF(COUNT(AA11:AH11)<8,"",AVERAGE(AA11:AH11))) | AY11: =IF($C11<>1,"",IF(COUNT(AI11:AL11)<4,"",AVERAGE(AI11:AL11))) | AZ11: =IF($C11<>1,"",IF(OR(K11="",M11=""),"",IF(AND(OR(K11=3,K11=4),M11=3),1,0))) | BA11: 1
A12: R011 | B12: 12 | C12: 1 | D12: 2 | E12: 1 | F12: 49 | G12: 1 | H12: 1 | J12: 3 | K12: 2 | M12: 2 | N12: 2 | O12: 2 | P12: 3 | Q12: 3 | R12: 2 | S12: 5 | T12: 2 | U12: 3 | V12: 3 | W12: 2 | X12: 2 | Y12: 2 | Z12: 2 | AA12: 4 | AB12: 4 | AC12: 4 | AD12: 4 | AE12: 3 | AF12: 3 | AG12: 4 | AH12: 4 | AI12: 3 | AJ12: 3 | AK12: 2 | AL12: 2 | AM12: =IF(COUNT(O12:V12)<8,"",AVERAGE(O12:V12)) | AN12: =IF(COUNT(O12:O12)<1,"",AVERAGE(O12:O12)) | AO12: =IF(COUNT(P12:P12)<1,"",AVERAGE(P12:P12)) | AP12: =IF(COUNT(Q12:R12)<2,"",AVERAGE(Q12:R12)) | AQ12: =IF(COUNT(S12:T12)<2,"",AVERAGE(S12:T12)) | AR12: =IF(COUNT(U12:V12)<2,"",AVERAGE(U12:V12)) | AS12: =IF(COUNT(W12:Z12)<4,"",AVERAGE(W12:Z12)) | AT12: =IF($C12<>1,"",IF(COUNT(AA12:AB12)<2,"",AVERAGE(AA12:AB12))) | AU12: =IF($C12<>1,"",IF(COUNT(AC12:AD12)<2,"",AVERAGE(AC12:AD12))) | AV12: =IF($C12<>1,"",IF(COUNT(AE12:AF12)<2,"",AVERAGE(AE12:AF12))) | AW12: =IF($C12<>1,"",IF(COUNT(AG12:AH12)<2,"",AVERAGE(AG12:AH12))) | AX12: =IF($C12<>1,"",IF(COUNT(AA12:AH12)<8,"",AVERAGE(AA12:AH12))) | AY12: =IF($C12<>1,"",IF(COUNT(AI12:AL12)<4,"",AVERAGE(AI12:AL12))) | AZ12: =IF($C12<>1,"",IF(OR(K12="",M12=""),"",IF(AND(OR(K12=3,K12=4),M12=3),1,0))) | BA12: 1
A13: R012 | B13: 13 | C13: 1 | D13: 2 | E13: 1 | F13: 30 | G13: 3 | H13: 1 | J13: 2 | K13: 4 | M13: 2 | N13: 2 | O13: 4 | P13: 5 | Q13: 3 | R13: 4 | S13: 4 | T13: 3 | U13: 4 | V13: 4 | W13: 2 | X13: 2 | Y13: 3 | Z13: 5 | AA13: 5 | AB13: 4 | AC13: 4 | AD13: 3 | AE13: 4 | AF13: 4 | AG13: 5 | AH13: 4 | AI13: 3 | AJ13: 2 | AK13: 2 | AL13: 2 | AM13: =IF(COUNT(O13:V13)<8,"",AVERAGE(O13:V13)) | AN13: =IF(COUNT(O13:O13)<1,"",AVERAGE(O13:O13)) | AO13: =IF(COUNT(P13:P13)<1,"",AVERAGE(P13:P13)) | AP13: =IF(COUNT(Q13:R13)<2,"",AVERAGE(Q13:R13)) | AQ13: =IF(COUNT(S13:T13)<2,"",AVERAGE(S13:T13)) | AR13: =IF(COUNT(U13:V13)<2,"",AVERAGE(U13:V13)) | AS13: =IF(COUNT(W13:Z13)<4,"",AVERAGE(W13:Z13)) | AT13: =IF($C13<>1,"",IF(COUNT(AA13:AB13)<2,"",AVERAGE(AA13:AB13))) | AU13: =IF($C13<>1,"",IF(COUNT(AC13:AD13)<2,"",AVERAGE(AC13:AD13))) | AV13: =IF($C13<>1,"",IF(COUNT(AE13:AF13)<2,"",AVERAGE(AE13:AF13))) | AW13: =IF($C13<>1,"",IF(COUNT(AG13:AH13)<2,"",AVERAGE(AG13:AH13))) | AX13: =IF($C13<>1,"",IF(COUNT(AA13:AH13)<8,"",AVERAGE(AA13:AH13))) | AY13: =IF($C13<>1,"",IF(COUNT(AI13:AL13)<4,"",AVERAGE(AI13:AL13))) | AZ13: =IF($C13<>1,"",IF(OR(K13="",M13=""),"",IF(AND(OR(K13=3,K13=4),M13=3),1,0))) | BA13: 1
A14: R013 | B14: 14 | C14: 1 | D14: 1 | E14: 1 | F14: 65 | G14: 12 | H14: 2 | J14: 4 | K14: 2 | M14: 4 | N14: 2 | O14: 3 | P14: 5 | Q14: 5 | R14: 5 | S14: 5 | T14: 5 | U14: 5 | V14: 5 | W14: 5 | X14: 5 | Y14: 5 | Z14: 5 | AA14: 5 | AB14: 5 | AC14: 5 | AD14: 5 | AE14: 5 | AF14: 5 | AG14: 5 | AH14: 5 | AI14: 5 | AJ14: 5 | AK14: 5 | AL14: 5 | AM14: =IF(COUNT(O14:V14)<8,"",AVERAGE(O14:V14)) | AN14: =IF(COUNT(O14:O14)<1,"",AVERAGE(O14:O14)) | AO14: =IF(COUNT(P14:P14)<1,"",AVERAGE(P14:P14)) | AP14: =IF(COUNT(Q14:R14)<2,"",AVERAGE(Q14:R14)) | AQ14: =IF(COUNT(S14:T14)<2,"",AVERAGE(S14:T14)) | AR14: =IF(COUNT(U14:V14)<2,"",AVERAGE(U14:V14)) | AS14: =IF(COUNT(W14:Z14)<4,"",AVERAGE(W14:Z14)) | AT14: =IF($C14<>1,"",IF(COUNT(AA14:AB14)<2,"",AVERAGE(AA14:AB14))) | AU14: =IF($C14<>1,"",IF(COUNT(AC14:AD14)<2,"",AVERAGE(AC14:AD14))) | AV14: =IF($C14<>1,"",IF(COUNT(AE14:AF14)<2,"",AVERAGE(AE14:AF14))) | AW14: =IF($C14<>1,"",IF(COUNT(AG14:AH14)<2,"",AVERAGE(AG14:AH14))) | AX14: =IF($C14<>1,"",IF(COUNT(AA14:AH14)<8,"",AVERAGE(AA14:AH14))) | AY14: =IF($C14<>1,"",IF(COUNT(AI14:AL14)<4,"",AVERAGE(AI14:AL14))) | AZ14: =IF($C14<>1,"",IF(OR(K14="",M14=""),"",IF(AND(OR(K14=3,K14=4),M14=3),1,0))) | BA14: 1
A15: R014 | B15: 15 | C15: 1 | D15: 1 | E15: 1 | F15: 53 | G15: 28 | H15: 3 | J15: 3 | K15: 3 | M15: 1 | N15: 1 | O15: 5 | P15: 5 | Q15: 5 | R15: 4 | S15: 4 | T15: 4 | U15: 5 | V15: 4 | W15: 4 | X15: 4 | Y15: 4 | Z15: 4 | AA15: 4 | AB15: 2 | AC15: 4 | AD15: 2 | AE15: 3 | AF15: 3 | AG15: 4 | AH15: 3 | AI15: 4 | AJ15: 4 | AK15: 2 | AL15: 4 | AM15: =IF(COUNT(O15:V15)<8,"",AVERAGE(O15:V15)) | AN15: =IF(COUNT(O15:O15)<1,"",AVERAGE(O15:O15)) | AO15: =IF(COUNT(P15:P15)<1,"",AVERAGE(P15:P15)) | AP15: =IF(COUNT(Q15:R15)<2,"",AVERAGE(Q15:R15)) | AQ15: =IF(COUNT(S15:T15)<2,"",AVERAGE(S15:T15)) | AR15: =IF(COUNT(U15:V15)<2,"",AVERAGE(U15:V15)) | AS15: =IF(COUNT(W15:Z15)<4,"",AVERAGE(W15:Z15)) | AT15: =IF($C15<>1,"",IF(COUNT(AA15:AB15)<2,"",AVERAGE(AA15:AB15))) | AU15: =IF($C15<>1,"",IF(COUNT(AC15:AD15)<2,"",AVERAGE(AC15:AD15))) | AV15: =IF($C15<>1,"",IF(COUNT(AE15:AF15)<2,"",AVERAGE(AE15:AF15))) | AW15: =IF($C15<>1,"",IF(COUNT(AG15:AH15)<2,"",AVERAGE(AG15:AH15))) | AX15: =IF($C15<>1,"",IF(COUNT(AA15:AH15)<8,"",AVERAGE(AA15:AH15))) | AY15: =IF($C15<>1,"",IF(COUNT(AI15:AL15)<4,"",AVERAGE(AI15:AL15))) | AZ15: =IF($C15<>1,"",IF(OR(K15="",M15=""),"",IF(AND(OR(K15=3,K15=4),M15=3),1,0))) | BA15: 1
A16: R015 | B16: 16 | C16: 1 | D16: 1 | E16: 1 | F16: 53 | G16: 23 | H16: 3 | J16: 3 | K16: 2 | M16: 2 | N16: 2 | O16: 4 | P16: 4 | Q16: 4 | R16: 3 | S16: 3 | T16: 4 | U16: 4 | V16: 4 | W16: 3 | X16: 3 | Y16: 5 | Z16: 4 | AA16: 3 | AB16: 3 | AC16: 3 | AD16: 3 | AE16: 3 | AF16: 3 | AG16: 4 | AH16: 4 | AI16: 3 | AJ16: 3 | AK16: 4 | AL16: 4 | AM16: =IF(COUNT(O16:V16)<8,"",AVERAGE(O16:V16)) | AN16: =IF(COUNT(O16:O16)<1,"",AVERAGE(O16:O16)) | AO16: =IF(COUNT(P16:P16)<1,"",AVERAGE(P16:P16)) | AP16: =IF(COUNT(Q16:R16)<2,"",AVERAGE(Q16:R16)) | AQ16: =IF(COUNT(S16:T16)<2,"",AVERAGE(S16:T16)) | AR16: =IF(COUNT(U16:V16)<2,"",AVERAGE(U16:V16)) | AS16: =IF(COUNT(W16:Z16)<4,"",AVERAGE(W16:Z16)) | AT16: =IF($C16<>1,"",IF(COUNT(AA16:AB16)<2,"",AVERAGE(AA16:AB16))) | AU16: =IF($C16<>1,"",IF(COUNT(AC16:AD16)<2,"",AVERAGE(AC16:AD16))) | AV16: =IF($C16<>1,"",IF(COUNT(AE16:AF16)<2,"",AVERAGE(AE16:AF16))) | AW16: =IF($C16<>1,"",IF(COUNT(AG16:AH16)<2,"",AVERAGE(AG16:AH16))) | AX16: =IF($C16<>1,"",IF(COUNT(AA16:AH16)<8,"",AVERAGE(AA16:AH16))) | AY16: =IF($C16<>1,"",IF(COUNT(AI16:AL16)<4,"",AVERAGE(AI16:AL16))) | AZ16: =IF($C16<>1,"",IF(OR(K16="",M16=""),"",IF(AND(OR(K16=3,K16=4),M16=3),1,0))) | BA16: 1
A17: R016 | B17: 17 | C17: 0 | D17: 1 | E17: 1 | F17: 52 | G17: 25 | H17: 3 | J17: 3 | K17: 3 | M17: 2 | N17: 1 | O17: 4 | P17: 4 | Q17: 3 | R17: 4 | S17: 4 | T17: 4 | U17: 4 | V17: 4 | W17: 2 | X17: 2 | Y17: 4 | Z17: 1 | AM17: =IF(COUNT(O17:V17)<8,"",AVERAGE(O17:V17)) | AN17: =IF(COUNT(O17:O17)<1,"",AVERAGE(O17:O17)) | AO17: =IF(COUNT(P17:P17)<1,"",AVERAGE(P17:P17)) | AP17: =IF(COUNT(Q17:R17)<2,"",AVERAGE(Q17:R17)) | AQ17: =IF(COUNT(S17:T17)<2,"",AVERAGE(S17:T17)) | AR17: =IF(COUNT(U17:V17)<2,"",AVERAGE(U17:V17)) | AS17: =IF(COUNT(W17:Z17)<4,"",AVERAGE(W17:Z17)) | AT17: =IF($C17<>1,"",IF(COUNT(AA17:AB17)<2,"",AVERAGE(AA17:AB17))) | AU17: =IF($C17<>1,"",IF(COUNT(AC17:AD17)<2,"",AVERAGE(AC17:AD17))) | AV17: =IF($C17<>1,"",IF(COUNT(AE17:AF17)<2,"",AVERAGE(AE17:AF17))) | AW17: =IF($C17<>1,"",IF(COUNT(AG17:AH17)<2,"",AVERAGE(AG17:AH17))) | AX17: =IF($C17<>1,"",IF(COUNT(AA17:AH17)<8,"",AVERAGE(AA17:AH17))) | AY17: =IF($C17<>1,"",IF(COUNT(AI17:AL17)<4,"",AVERAGE(AI17:AL17))) | AZ17: =IF($C17<>1,"",IF(OR(K17="",M17=""),"",IF(AND(OR(K17=3,K17=4),M17=3),1,0))) | BA17: 1
A18: R017 | B18: 18 | C18: 1 | D18: 2 | E18: 1 | F18: 54 | G18: 20 | H18: 1 | J18: 4 | K18: 4 | M18: 3 | N18: 2 | O18: 3 | P18: 4 | Q18: 4 | R18: 4 | S18: 4 | T18: 4 | U18: 4 | V18: 4 | W18: 2 | X18: 2 | Y18: 2 | Z18: 2 | AA18: 3 | AB18: 4 | AC18: 4 | AD18: 4 | AE18: 3 | AF18: 3 | AG18: 4 | AH18: 3 | AI18: 4 | AJ18: 4 | AK18: 4 | AL18: 4 | AM18: =IF(COUNT(O18:V18)<8,"",AVERAGE(O18:V18)) | AN18: =IF(COUNT(O18:O18)<1,"",AVERAGE(O18:O18)) | AO18: =IF(COUNT(P18:P18)<1,"",AVERAGE(P18:P18)) | AP18: =IF(COUNT(Q18:R18)<2,"",AVERAGE(Q18:R18)) | AQ18: =IF(COUNT(S18:T18)<2,"",AVERAGE(S18:T18)) | AR18: =IF(COUNT(U18:V18)<2,"",AVERAGE(U18:V18)) | AS18: =IF(COUNT(W18:Z18)<4,"",AVERAGE(W18:Z18)) | AT18: =IF($C18<>1,"",IF(COUNT(AA18:AB18)<2,"",AVERAGE(AA18:AB18))) | AU18: =IF($C18<>1,"",IF(COUNT(AC18:AD18)<2,"",AVERAGE(AC18:AD18))) | AV18: =IF($C18<>1,"",IF(COUNT(AE18:AF18)<2,"",AVERAGE(AE18:AF18))) | AW18: =IF($C18<>1,"",IF(COUNT(AG18:AH18)<2,"",AVERAGE(AG18:AH18))) | AX18: =IF($C18<>1,"",IF(COUNT(AA18:AH18)<8,"",AVERAGE(AA18:AH18))) | AY18: =IF($C18<>1,"",IF(COUNT(AI18:AL18)<4,"",AVERAGE(AI18:AL18))) | AZ18: =IF($C18<>1,"",IF(OR(K18="",M18=""),"",IF(AND(OR(K18=3,K18=4),M18=3),1,0))) | BA18: 1
A19: R018 | B19: 19 | C19: 0 | D19: 1 | E19: 1 | F19: 28 | G19: 3 | H19: 2 | J19: 4 | K19: 2 | M19: 2 | N19: 2 | O19: 3 | P19: 3 | Q19: 2 | R19: 2 | S19: 2 | T19: 1 | U19: 2 | V19: 4 | W19: 1 | X19: 1 | Y19: 1 | Z19: 1 | AM19: =IF(COUNT(O19:V19)<8,"",AVERAGE(O19:V19)) | AN19: =IF(COUNT(O19:O19)<1,"",AVERAGE(O19:O19)) | AO19: =IF(COUNT(P19:P19)<1,"",AVERAGE(P19:P19)) | AP19: =IF(COUNT(Q19:R19)<2,"",AVERAGE(Q19:R19)) | AQ19: =IF(COUNT(S19:T19)<2,"",AVERAGE(S19:T19)) | AR19: =IF(COUNT(U19:V19)<2,"",AVERAGE(U19:V19)) | AS19: =IF(COUNT(W19:Z19)<4,"",AVERAGE(W19:Z19)) | AT19: =IF($C19<>1,"",IF(COUNT(AA19:AB19)<2,"",AVERAGE(AA19:AB19))) | AU19: =IF($C19<>1,"",IF(COUNT(AC19:AD19)<2,"",AVERAGE(AC19:AD19))) | AV19: =IF($C19<>1,"",IF(COUNT(AE19:AF19)<2,"",AVERAGE(AE19:AF19))) | AW19: =IF($C19<>1,"",IF(COUNT(AG19:AH19)<2,"",AVERAGE(AG19:AH19))) | AX19: =IF($C19<>1,"",IF(COUNT(AA19:AH19)<8,"",AVERAGE(AA19:AH19))) | AY19: =IF($C19<>1,"",IF(COUNT(AI19:AL19)<4,"",AVERAGE(AI19:AL19))) | AZ19: =IF($C19<>1,"",IF(OR(K19="",M19=""),"",IF(AND(OR(K19=3,K19=4),M19=3),1,0))) | BA19: 1
A20: R019 | B20: 20 | C20: 1 | D20: 2 | E20: 1 | F20: 34 | G20: 2 | H20: 1 | J20: 2 | K20: 2 | M20: 1 | N20: 2 | O20: 3 | P20: 4 | Q20: 4 | R20: 4 | S20: 3 | T20: 3 | U20: 4 | V20: 4 | W20: 3 | X20: 3 | Y20: 3 | Z20: 3 | AA20: 3 | AB20: 4 | AC20: 3 | AD20: 3 | AE20: 2 | AF20: 3 | AG20: 4 | AH20: 3 | AI20: 4 | AJ20: 4 | AK20: 4 | AL20: 3 | AM20: =IF(COUNT(O20:V20)<8,"",AVERAGE(O20:V20)) | AN20: =IF(COUNT(O20:O20)<1,"",AVERAGE(O20:O20)) | AO20: =IF(COUNT(P20:P20)<1,"",AVERAGE(P20:P20)) | AP20: =IF(COUNT(Q20:R20)<2,"",AVERAGE(Q20:R20)) | AQ20: =IF(COUNT(S20:T20)<2,"",AVERAGE(S20:T20)) | AR20: =IF(COUNT(U20:V20)<2,"",AVERAGE(U20:V20)) | AS20: =IF(COUNT(W20:Z20)<4,"",AVERAGE(W20:Z20)) | AT20: =IF($C20<>1,"",IF(COUNT(AA20:AB20)<2,"",AVERAGE(AA20:AB20))) | AU20: =IF($C20<>1,"",IF(COUNT(AC20:AD20)<2,"",AVERAGE(AC20:AD20))) | AV20: =IF($C20<>1,"",IF(COUNT(AE20:AF20)<2,"",AVERAGE(AE20:AF20))) | AW20: =IF($C20<>1,"",IF(COUNT(AG20:AH20)<2,"",AVERAGE(AG20:AH20))) | AX20: =IF($C20<>1,"",IF(COUNT(AA20:AH20)<8,"",AVERAGE(AA20:AH20))) | AY20: =IF($C20<>1,"",IF(COUNT(AI20:AL20)<4,"",AVERAGE(AI20:AL20))) | AZ20: =IF($C20<>1,"",IF(OR(K20="",M20=""),"",IF(AND(OR(K20=3,K20=4),M20=3),1,0))) | BA20: 1
A21: R020 | B21: 21 | C21: 0 | D21: 1 | E21: 1 | F21: 65 | G21: 45 | H21: 3 | J21: 2 | K21: 5 | L21: 현장상주 | M21: 1 | N21: 1 | O21: 5 | P21: 5 | Q21: 5 | R21: 5 | S21: 5 | T21: 5 | U21: 5 | V21: 5 | W21: 1 | X21: 1 | Y21: 1 | Z21: 1 | AM21: =IF(COUNT(O21:V21)<8,"",AVERAGE(O21:V21)) | AN21: =IF(COUNT(O21:O21)<1,"",AVERAGE(O21:O21)) | AO21: =IF(COUNT(P21:P21)<1,"",AVERAGE(P21:P21)) | AP21: =IF(COUNT(Q21:R21)<2,"",AVERAGE(Q21:R21)) | AQ21: =IF(COUNT(S21:T21)<2,"",AVERAGE(S21:T21)) | AR21: =IF(COUNT(U21:V21)<2,"",AVERAGE(U21:V21)) | AS21: =IF(COUNT(W21:Z21)<4,"",AVERAGE(W21:Z21)) | AT21: =IF($C21<>1,"",IF(COUNT(AA21:AB21)<2,"",AVERAGE(AA21:AB21))) | AU21: =IF($C21<>1,"",IF(COUNT(AC21:AD21)<2,"",AVERAGE(AC21:AD21))) | AV21: =IF($C21<>1,"",IF(COUNT(AE21:AF21)<2,"",AVERAGE(AE21:AF21))) | AW21: =IF($C21<>1,"",IF(COUNT(AG21:AH21)<2,"",AVERAGE(AG21:AH21))) | AX21: =IF($C21<>1,"",IF(COUNT(AA21:AH21)<8,"",AVERAGE(AA21:AH21))) | AY21: =IF($C21<>1,"",IF(COUNT(AI21:AL21)<4,"",AVERAGE(AI21:AL21))) | AZ21: =IF($C21<>1,"",IF(OR(K21="",M21=""),"",IF(AND(OR(K21=3,K21=4),M21=3),1,0))) | BA21: 1
A22: R021 | B22: 22 | C22: 1 | D22: 1 | E22: 1 | F22: 66 | G22: 33 | H22: 3 | J22: 1 | K22: 2 | M22: 1 | N22: 1 | O22: 5 | P22: 5 | Q22: 4 | R22: 4 | S22: 5 | T22: 4 | U22: 5 | V22: 5 | W22: 5 | X22: 5 | Y22: 5 | Z22: 5 | AA22: 1 | AB22: 2 | AC22: 4 | AD22: 4 | AE22: 5 | AF22: 5 | AG22: 5 | AH22: 5 | AI22: 5 | AJ22: 5 | AK22: 5 | AL22: 5 | AM22: =IF(COUNT(O22:V22)<8,"",AVERAGE(O22:V22)) | AN22: =IF(COUNT(O22:O22)<1,"",AVERAGE(O22:O22)) | AO22: =IF(COUNT(P22:P22)<1,"",AVERAGE(P22:P22)) | AP22: =IF(COUNT(Q22:R22)<2,"",AVERAGE(Q22:R22)) | AQ22: =IF(COUNT(S22:T22)<2,"",AVERAGE(S22:T22)) | AR22: =IF(COUNT(U22:V22)<2,"",AVERAGE(U22:V22)) | AS22: =IF(COUNT(W22:Z22)<4,"",AVERAGE(W22:Z22)) | AT22: =IF($C22<>1,"",IF(COUNT(AA22:AB22)<2,"",AVERAGE(AA22:AB22))) | AU22: =IF($C22<>1,"",IF(COUNT(AC22:AD22)<2,"",AVERAGE(AC22:AD22))) | AV22: =IF($C22<>1,"",IF(COUNT(AE22:AF22)<2,"",AVERAGE(AE22:AF22))) | AW22: =IF($C22<>1,"",IF(COUNT(AG22:AH22)<2,"",AVERAGE(AG22:AH22))) | AX22: =IF($C22<>1,"",IF(COUNT(AA22:AH22)<8,"",AVERAGE(AA22:AH22))) | AY22: =IF($C22<>1,"",IF(COUNT(AI22:AL22)<4,"",AVERAGE(AI22:AL22))) | AZ22: =IF($C22<>1,"",IF(OR(K22="",M22=""),"",IF(AND(OR(K22=3,K22=4),M22=3),1,0))) | BA22: 1
A23: R022 | B23: 23 | C23: 0 | D23: 1 | E23: 1 | F23: 56 | G23: 30 | H23: 3 | J23: 2 | K23: 2 | M23: 2 | N23: 2 | O23: 4 | P23: 5 | Q23: 3 | R23: 3 | S23: 3 | T23: 3 | U23: 4 | V23: 4 | W23: 3 | X23: 2 | Y23: 2 | Z23: 3 | AM23: =IF(COUNT(O23:V23)<8,"",AVERAGE(O23:V23)) | AN23: =IF(COUNT(O23:O23)<1,"",AVERAGE(O23:O23)) | AO23: =IF(COUNT(P23:P23)<1,"",AVERAGE(P23:P23)) | AP23: =IF(COUNT(Q23:R23)<2,"",AVERAGE(Q23:R23)) | AQ23: =IF(COUNT(S23:T23)<2,"",AVERAGE(S23:T23)) | AR23: =IF(COUNT(U23:V23)<2,"",AVERAGE(U23:V23)) | AS23: =IF(COUNT(W23:Z23)<4,"",AVERAGE(W23:Z23)) | AT23: =IF($C23<>1,"",IF(COUNT(AA23:AB23)<2,"",AVERAGE(AA23:AB23))) | AU23: =IF($C23<>1,"",IF(COUNT(AC23:AD23)<2,"",AVERAGE(AC23:AD23))) | AV23: =IF($C23<>1,"",IF(COUNT(AE23:AF23)<2,"",AVERAGE(AE23:AF23))) | AW23: =IF($C23<>1,"",IF(COUNT(AG23:AH23)<2,"",AVERAGE(AG23:AH23))) | AX23: =IF($C23<>1,"",IF(COUNT(AA23:AH23)<8,"",AVERAGE(AA23:AH23))) | AY23: =IF($C23<>1,"",IF(COUNT(AI23:AL23)<4,"",AVERAGE(AI23:AL23))) | AZ23: =IF($C23<>1,"",IF(OR(K23="",M23=""),"",IF(AND(OR(K23=3,K23=4),M23=3),1,0))) | BA23: 1
A24: R023 | B24: 24 | C24: 0 | D24: 1 | E24: 1 | F24: 63 | G24: 33 | H24: 2 | J24: 4 | K24: 2 | M24: 1 | N24: 3 | O24: 3 | P24: 4 | Q24: 2 | R24: 2 | S24: 3 | T24: 3 | U24: 3 | V24: 3 | W24: 4 | X24: 4 | Y24: 4 | Z24: 4 | AM24: =IF(COUNT(O24:V24)<8,"",AVERAGE(O24:V24)) | AN24: =IF(COUNT(O24:O24)<1,"",AVERAGE(O24:O24)) | AO24: =IF(COUNT(P24:P24)<1,"",AVERAGE(P24:P24)) | AP24: =IF(COUNT(Q24:R24)<2,"",AVERAGE(Q24:R24)) | AQ24: =IF(COUNT(S24:T24)<2,"",AVERAGE(S24:T24)) | AR24: =IF(COUNT(U24:V24)<2,"",AVERAGE(U24:V24)) | AS24: =IF(COUNT(W24:Z24)<4,"",AVERAGE(W24:Z24)) | AT24: =IF($C24<>1,"",IF(COUNT(AA24:AB24)<2,"",AVERAGE(AA24:AB24))) | AU24: =IF($C24<>1,"",IF(COUNT(AC24:AD24)<2,"",AVERAGE(AC24:AD24))) | AV24: =IF($C24<>1,"",IF(COUNT(AE24:AF24)<2,"",AVERAGE(AE24:AF24))) | AW24: =IF($C24<>1,"",IF(COUNT(AG24:AH24)<2,"",AVERAGE(AG24:AH24))) | AX24: =IF($C24<>1,"",IF(COUNT(AA24:AH24)<8,"",AVERAGE(AA24:AH24))) | AY24: =IF($C24<>1,"",IF(COUNT(AI24:AL24)<4,"",AVERAGE(AI24:AL24))) | AZ24: =IF($C24<>1,"",IF(OR(K24="",M24=""),"",IF(AND(OR(K24=3,K24=4),M24=3),1,0))) | BA24: 1
A25: R024 | B25: 25 | C25: 1 | D25: 1 | E25: 1 | F25: 64 | G25: 1 | H25: 3 | J25: 3 | K25: 5 | L25: 수시로 현장을 답사하여 확인한다 | M25: 2 | N25: 1 | O25: 5 | P25: 5 | Q25: 5 | R25: 5 | S25: 5 | T25: 5 | U25: 5 | V25: 5 | W25: 3 | X25: 1 | Y25: 1 | Z25: 1 | AA25: 5 | AB25: 5 | AC25: 5 | AD25: 1 | AE25: 2 | AF25: 3 | AG25: 5 | AH25: 5 | AI25: 1 | AJ25: 1 | AK25: 5 | AL25: 1 | AM25: =IF(COUNT(O25:V25)<8,"",AVERAGE(O25:V25)) | AN25: =IF(COUNT(O25:O25)<1,"",AVERAGE(O25:O25)) | AO25: =IF(COUNT(P25:P25)<1,"",AVERAGE(P25:P25)) | AP25: =IF(COUNT(Q25:R25)<2,"",AVERAGE(Q25:R25)) | AQ25: =IF(COUNT(S25:T25)<2,"",AVERAGE(S25:T25)) | AR25: =IF(COUNT(U25:V25)<2,"",AVERAGE(U25:V25)) | AS25: =IF(COUNT(W25:Z25)<4,"",AVERAGE(W25:Z25)) | AT25: =IF($C25<>1,"",IF(COUNT(AA25:AB25)<2,"",AVERAGE(AA25:AB25))) | AU25: =IF($C25<>1,"",IF(COUNT(AC25:AD25)<2,"",AVERAGE(AC25:AD25))) | AV25: =IF($C25<>1,"",IF(COUNT(AE25:AF25)<2,"",AVERAGE(AE25:AF25))) | AW25: =IF($C25<>1,"",IF(COUNT(AG25:AH25)<2,"",AVERAGE(AG25:AH25))) | AX25: =IF($C25<>1,"",IF(COUNT(AA25:AH25)<8,"",AVERAGE(AA25:AH25))) | AY25: =IF($C25<>1,"",IF(COUNT(AI25:AL25)<4,"",AVERAGE(AI25:AL25))) | AZ25: =IF($C25<>1,"",IF(OR(K25="",M25=""),"",IF(AND(OR(K25=3,K25=4),M25=3),1,0))) | BA25: 1
A26: R025 | B26: 26 | C26: 0 | D26: 1 | E26: 1 | F26: 48 | G26: 25 | H26: 3 | J26: 4 | K26: 3 | M26: 3 | N26: 1 | O26: 5 | P26: 5 | Q26: 5 | R26: 5 | S26: 5 | T26: 5 | U26: 5 | V26: 5 | W26: 2 | X26: 4 | Y26: 2 | Z26: 2 | AM26: =IF(COUNT(O26:V26)<8,"",AVERAGE(O26:V26)) | AN26: =IF(COUNT(O26:O26)<1,"",AVERAGE(O26:O26)) | AO26: =IF(COUNT(P26:P26)<1,"",AVERAGE(P26:P26)) | AP26: =IF(COUNT(Q26:R26)<2,"",AVERAGE(Q26:R26)) | AQ26: =IF(COUNT(S26:T26)<2,"",AVERAGE(S26:T26)) | AR26: =IF(COUNT(U26:V26)<2,"",AVERAGE(U26:V26)) | AS26: =IF(COUNT(W26:Z26)<4,"",AVERAGE(W26:Z26)) | AT26: =IF($C26<>1,"",IF(COUNT(AA26:AB26)<2,"",AVERAGE(AA26:AB26))) | AU26: =IF($C26<>1,"",IF(COUNT(AC26:AD26)<2,"",AVERAGE(AC26:AD26))) | AV26: =IF($C26<>1,"",IF(COUNT(AE26:AF26)<2,"",AVERAGE(AE26:AF26))) | AW26: =IF($C26<>1,"",IF(COUNT(AG26:AH26)<2,"",AVERAGE(AG26:AH26))) | AX26: =IF($C26<>1,"",IF(COUNT(AA26:AH26)<8,"",AVERAGE(AA26:AH26))) | AY26: =IF($C26<>1,"",IF(COUNT(AI26:AL26)<4,"",AVERAGE(AI26:AL26))) | AZ26: =IF($C26<>1,"",IF(OR(K26="",M26=""),"",IF(AND(OR(K26=3,K26=4),M26=3),1,0))) | BA26: 1
A27: R026 | B27: 27 | C27: 1 | D27: 2 | E27: 1 | F27: 45 | G27: 12 | H27: 1 | J27: 3 | K27: 3 | M27: 2 | N27: 2 | O27: 5 | P27: 5 | Q27: 5 | R27: 5 | S27: 5 | T27: 5 | U27: 5 | V27: 5 | W27: 2 | X27: 2 | Y27: 2 | Z27: 5 | AA27: 5 | AB27: 5 | AC27: 5 | AD27: 5 | AE27: 5 | AF27: 5 | AG27: 5 | AH27: 5 | AI27: 5 | AJ27: 5 | AK27: 5 | AL27: 5 | AM27: =IF(COUNT(O27:V27)<8,"",AVERAGE(O27:V27)) | AN27: =IF(COUNT(O27:O27)<1,"",AVERAGE(O27:O27)) | AO27: =IF(COUNT(P27:P27)<1,"",AVERAGE(P27:P27)) | AP27: =IF(COUNT(Q27:R27)<2,"",AVERAGE(Q27:R27)) | AQ27: =IF(COUNT(S27:T27)<2,"",AVERAGE(S27:T27)) | AR27: =IF(COUNT(U27:V27)<2,"",AVERAGE(U27:V27)) | AS27: =IF(COUNT(W27:Z27)<4,"",AVERAGE(W27:Z27)) | AT27: =IF($C27<>1,"",IF(COUNT(AA27:AB27)<2,"",AVERAGE(AA27:AB27))) | AU27: =IF($C27<>1,"",IF(COUNT(AC27:AD27)<2,"",AVERAGE(AC27:AD27))) | AV27: =IF($C27<>1,"",IF(COUNT(AE27:AF27)<2,"",AVERAGE(AE27:AF27))) | AW27: =IF($C27<>1,"",IF(COUNT(AG27:AH27)<2,"",AVERAGE(AG27:AH27))) | AX27: =IF($C27<>1,"",IF(COUNT(AA27:AH27)<8,"",AVERAGE(AA27:AH27))) | AY27: =IF($C27<>1,"",IF(COUNT(AI27:AL27)<4,"",AVERAGE(AI27:AL27))) | AZ27: =IF($C27<>1,"",IF(OR(K27="",M27=""),"",IF(AND(OR(K27=3,K27=4),M27=3),1,0))) | BA27: 1
A28: R027 | B28: 28 | C28: 0 | D28: 2 | E28: 1 | F28: 39 | G28: 15 | H28: 1 | J28: 1 | K28: 1 | M28: 2 | N28: 2 | O28: 2 | P28: 3 | Q28: 1 | R28: 2 | S28: 2 | T28: 1 | U28: 2 | V28: 2 | W28: 5 | X28: 4 | Y28: 4 | Z28: 4 | AM28: =IF(COUNT(O28:V28)<8,"",AVERAGE(O28:V28)) | AN28: =IF(COUNT(O28:O28)<1,"",AVERAGE(O28:O28)) | AO28: =IF(COUNT(P28:P28)<1,"",AVERAGE(P28:P28)) | AP28: =IF(COUNT(Q28:R28)<2,"",AVERAGE(Q28:R28)) | AQ28: =IF(COUNT(S28:T28)<2,"",AVERAGE(S28:T28)) | AR28: =IF(COUNT(U28:V28)<2,"",AVERAGE(U28:V28)) | AS28: =IF(COUNT(W28:Z28)<4,"",AVERAGE(W28:Z28)) | AT28: =IF($C28<>1,"",IF(COUNT(AA28:AB28)<2,"",AVERAGE(AA28:AB28))) | AU28: =IF($C28<>1,"",IF(COUNT(AC28:AD28)<2,"",AVERAGE(AC28:AD28))) | AV28: =IF($C28<>1,"",IF(COUNT(AE28:AF28)<2,"",AVERAGE(AE28:AF28))) | AW28: =IF($C28<>1,"",IF(COUNT(AG28:AH28)<2,"",AVERAGE(AG28:AH28))) | AX28: =IF($C28<>1,"",IF(COUNT(AA28:AH28)<8,"",AVERAGE(AA28:AH28))) | AY28: =IF($C28<>1,"",IF(COUNT(AI28:AL28)<4,"",AVERAGE(AI28:AL28))) | AZ28: =IF($C28<>1,"",IF(OR(K28="",M28=""),"",IF(AND(OR(K28=3,K28=4),M28=3),1,0))) | BA28: 1
A29: R028 | B29: 29 | C29: 1 | D29: 1 | E29: 1 | F29: 37 | G29: 11 | H29: 2 | J29: 4 | K29: 4 | M29: 1 | N29: 2 | O29: 4 | P29: 4 | Q29: 4 | R29: 3 | S29: 3 | T29: 3 | U29: 5 | V29: 5 | W29: 3 | X29: 3 | Y29: 4 | Z29: 5 | AA29: 3 | AB29: 2 | AC29: 3 | AD29: 2 | AE29: 3 | AF29: 3 | AG29: 2 | AH29: 3 | AI29: 3 | AJ29: 3 | AK29: 4 | AL29: 3 | AM29: =IF(COUNT(O29:V29)<8,"",AVERAGE(O29:V29)) | AN29: =IF(COUNT(O29:O29)<1,"",AVERAGE(O29:O29)) | AO29: =IF(COUNT(P29:P29)<1,"",AVERAGE(P29:P29)) | AP29: =IF(COUNT(Q29:R29)<2,"",AVERAGE(Q29:R29)) | AQ29: =IF(COUNT(S29:T29)<2,"",AVERAGE(S29:T29)) | AR29: =IF(COUNT(U29:V29)<2,"",AVERAGE(U29:V29)) | AS29: =IF(COUNT(W29:Z29)<4,"",AVERAGE(W29:Z29)) | AT29: =IF($C29<>1,"",IF(COUNT(AA29:AB29)<2,"",AVERAGE(AA29:AB29))) | AU29: =IF($C29<>1,"",IF(COUNT(AC29:AD29)<2,"",AVERAGE(AC29:AD29))) | AV29: =IF($C29<>1,"",IF(COUNT(AE29:AF29)<2,"",AVERAGE(AE29:AF29))) | AW29: =IF($C29<>1,"",IF(COUNT(AG29:AH29)<2,"",AVERAGE(AG29:AH29))) | AX29: =IF($C29<>1,"",IF(COUNT(AA29:AH29)<8,"",AVERAGE(AA29:AH29))) | AY29: =IF($C29<>1,"",IF(COUNT(AI29:AL29)<4,"",AVERAGE(AI29:AL29))) | AZ29: =IF($C29<>1,"",IF(OR(K29="",M29=""),"",IF(AND(OR(K29=3,K29=4),M29=3),1,0))) | BA29: 1
A30: R029 | B30: 30 | C30: 0 | D30: 1 | E30: 1 | F30: 32 | G30: 5 | H30: 2 | J30: 4 | K30: 3 | M30: 2 | N30: 1 | O30: 4 | P30: 4 | Q30: 3 | R30: 4 | S30: 4 | T30: 5 | U30: 5 | V30: 5 | W30: 4 | X30: 4 | Y30: 3 | Z30: 4 | AM30: =IF(COUNT(O30:V30)<8,"",AVERAGE(O30:V30)) | AN30: =IF(COUNT(O30:O30)<1,"",AVERAGE(O30:O30)) | AO30: =IF(COUNT(P30:P30)<1,"",AVERAGE(P30:P30)) | AP30: =IF(COUNT(Q30:R30)<2,"",AVERAGE(Q30:R30)) | AQ30: =IF(COUNT(S30:T30)<2,"",AVERAGE(S30:T30)) | AR30: =IF(COUNT(U30:V30)<2,"",AVERAGE(U30:V30)) | AS30: =IF(COUNT(W30:Z30)<4,"",AVERAGE(W30:Z30)) | AT30: =IF($C30<>1,"",IF(COUNT(AA30:AB30)<2,"",AVERAGE(AA30:AB30))) | AU30: =IF($C30<>1,"",IF(COUNT(AC30:AD30)<2,"",AVERAGE(AC30:AD30))) | AV30: =IF($C30<>1,"",IF(COUNT(AE30:AF30)<2,"",AVERAGE(AE30:AF30))) | AW30: =IF($C30<>1,"",IF(COUNT(AG30:AH30)<2,"",AVERAGE(AG30:AH30))) | AX30: =IF($C30<>1,"",IF(COUNT(AA30:AH30)<8,"",AVERAGE(AA30:AH30))) | AY30: =IF($C30<>1,"",IF(COUNT(AI30:AL30)<4,"",AVERAGE(AI30:AL30))) | AZ30: =IF($C30<>1,"",IF(OR(K30="",M30=""),"",IF(AND(OR(K30=3,K30=4),M30=3),1,0))) | BA30: 1
A31: R030 | B31: 31 | C31: 0 | D31: 2 | E31: 2 | F31: 24 | G31: 1 | J31: 2 | K31: 2 | M31: 2 | N31: 2 | O31: 4 | P31: 4 | Q31: 4 | R31: 4 | S31: 4 | T31: 4 | U31: 4 | V31: 4 | W31: 4 | X31: 4 | Y31: 4 | Z31: 4 | AM31: =IF(COUNT(O31:V31)<8,"",AVERAGE(O31:V31)) | AN31: =IF(COUNT(O31:O31)<1,"",AVERAGE(O31:O31)) | AO31: =IF(COUNT(P31:P31)<1,"",AVERAGE(P31:P31)) | AP31: =IF(COUNT(Q31:R31)<2,"",AVERAGE(Q31:R31)) | AQ31: =IF(COUNT(S31:T31)<2,"",AVERAGE(S31:T31)) | AR31: =IF(COUNT(U31:V31)<2,"",AVERAGE(U31:V31)) | AS31: =IF(COUNT(W31:Z31)<4,"",AVERAGE(W31:Z31)) | AT31: =IF($C31<>1,"",IF(COUNT(AA31:AB31)<2,"",AVERAGE(AA31:AB31))) | AU31: =IF($C31<>1,"",IF(COUNT(AC31:AD31)<2,"",AVERAGE(AC31:AD31))) | AV31: =IF($C31<>1,"",IF(COUNT(AE31:AF31)<2,"",AVERAGE(AE31:AF31))) | AW31: =IF($C31<>1,"",IF(COUNT(AG31:AH31)<2,"",AVERAGE(AG31:AH31))) | AX31: =IF($C31<>1,"",IF(COUNT(AA31:AH31)<8,"",AVERAGE(AA31:AH31))) | AY31: =IF($C31<>1,"",IF(COUNT(AI31:AL31)<4,"",AVERAGE(AI31:AL31))) | AZ31: =IF($C31<>1,"",IF(OR(K31="",M31=""),"",IF(AND(OR(K31=3,K31=4),M31=3),1,0))) | BA31: 1
A32: R031 | B32: 32 | C32: 1 | D32: 2 | E32: 1 | F32: 30 | G32: 4 | H32: 1 | J32: 3 | K32: 2 | M32: 2 | N32: 3 | O32: 4 | P32: 4 | Q32: 4 | R32: 4 | S32: 4 | T32: 4 | U32: 4 | V32: 4 | W32: 2 | X32: 2 | Y32: 2 | Z32: 2 | AA32: 4 | AB32: 4 | AC32: 4 | AD32: 4 | AE32: 2 | AF32: 2 | AG32: 4 | AH32: 3 | AI32: 1 | AJ32: 2 | AK32: 5 | AL32: 3 | AM32: =IF(COUNT(O32:V32)<8,"",AVERAGE(O32:V32)) | AN32: =IF(COUNT(O32:O32)<1,"",AVERAGE(O32:O32)) | AO32: =IF(COUNT(P32:P32)<1,"",AVERAGE(P32:P32)) | AP32: =IF(COUNT(Q32:R32)<2,"",AVERAGE(Q32:R32)) | AQ32: =IF(COUNT(S32:T32)<2,"",AVERAGE(S32:T32)) | AR32: =IF(COUNT(U32:V32)<2,"",AVERAGE(U32:V32)) | AS32: =IF(COUNT(W32:Z32)<4,"",AVERAGE(W32:Z32)) | AT32: =IF($C32<>1,"",IF(COUNT(AA32:AB32)<2,"",AVERAGE(AA32:AB32))) | AU32: =IF($C32<>1,"",IF(COUNT(AC32:AD32)<2,"",AVERAGE(AC32:AD32))) | AV32: =IF($C32<>1,"",IF(COUNT(AE32:AF32)<2,"",AVERAGE(AE32:AF32))) | AW32: =IF($C32<>1,"",IF(COUNT(AG32:AH32)<2,"",AVERAGE(AG32:AH32))) | AX32: =IF($C32<>1,"",IF(COUNT(AA32:AH32)<8,"",AVERAGE(AA32:AH32))) | AY32: =IF($C32<>1,"",IF(COUNT(AI32:AL32)<4,"",AVERAGE(AI32:AL32))) | AZ32: =IF($C32<>1,"",IF(OR(K32="",M32=""),"",IF(AND(OR(K32=3,K32=4),M32=3),1,0))) | BA32: 1
A33: R032 | B33: 33 | C33: 0 | D33: 2 | E33: 1 | F33: 52 | G33: 28 | H33: 1 | J33: 4 | K33: 3 | M33: 4 | N33: 3 | O33: 3 | P33: 3 | Q33: 3 | R33: 3 | S33: 3 | T33: 3 | U33: 4 | V33: 3 | W33: 5 | X33: 4 | Y33: 5 | Z33: 5 | AM33: =IF(COUNT(O33:V33)<8,"",AVERAGE(O33:V33)) | AN33: =IF(COUNT(O33:O33)<1,"",AVERAGE(O33:O33)) | AO33: =IF(COUNT(P33:P33)<1,"",AVERAGE(P33:P33)) | AP33: =IF(COUNT(Q33:R33)<2,"",AVERAGE(Q33:R33)) | AQ33: =IF(COUNT(S33:T33)<2,"",AVERAGE(S33:T33)) | AR33: =IF(COUNT(U33:V33)<2,"",AVERAGE(U33:V33)) | AS33: =IF(COUNT(W33:Z33)<4,"",AVERAGE(W33:Z33)) | AT33: =IF($C33<>1,"",IF(COUNT(AA33:AB33)<2,"",AVERAGE(AA33:AB33))) | AU33: =IF($C33<>1,"",IF(COUNT(AC33:AD33)<2,"",AVERAGE(AC33:AD33))) | AV33: =IF($C33<>1,"",IF(COUNT(AE33:AF33)<2,"",AVERAGE(AE33:AF33))) | AW33: =IF($C33<>1,"",IF(COUNT(AG33:AH33)<2,"",AVERAGE(AG33:AH33))) | AX33: =IF($C33<>1,"",IF(COUNT(AA33:AH33)<8,"",AVERAGE(AA33:AH33))) | AY33: =IF($C33<>1,"",IF(COUNT(AI33:AL33)<4,"",AVERAGE(AI33:AL33))) | AZ33: =IF($C33<>1,"",IF(OR(K33="",M33=""),"",IF(AND(OR(K33=3,K33=4),M33=3),1,0))) | BA33: 1
A34: R033 | B34: 34 | C34: 1 | D34: 1 | E34: 1 | F34: 51 | G34: 30 | H34: 3 | J34: 3 | K34: 5 | L34: 현장상주 미상주시 대체직원 상주 | M34: 1 | N34: 1 | O34: 4 | P34: 4 | Q34: 4 | R34: 4 | S34: 4 | T34: 4 | U34: 4 | V34: 4 | W34: 4 | X34: 3 | Y34: 4 | Z34: 3 | AA34: 4 | AB34: 4 | AC34: 4 | AD34: 4 | AE34: 3 | AF34: 3 | AG34: 3 | AH34: 3 | AI34: 3 | AJ34: 3 | AK34: 4 | AL34: 3 | AM34: =IF(COUNT(O34:V34)<8,"",AVERAGE(O34:V34)) | AN34: =IF(COUNT(O34:O34)<1,"",AVERAGE(O34:O34)) | AO34: =IF(COUNT(P34:P34)<1,"",AVERAGE(P34:P34)) | AP34: =IF(COUNT(Q34:R34)<2,"",AVERAGE(Q34:R34)) | AQ34: =IF(COUNT(S34:T34)<2,"",AVERAGE(S34:T34)) | AR34: =IF(COUNT(U34:V34)<2,"",AVERAGE(U34:V34)) | AS34: =IF(COUNT(W34:Z34)<4,"",AVERAGE(W34:Z34)) | AT34: =IF($C34<>1,"",IF(COUNT(AA34:AB34)<2,"",AVERAGE(AA34:AB34))) | AU34: =IF($C34<>1,"",IF(COUNT(AC34:AD34)<2,"",AVERAGE(AC34:AD34))) | AV34: =IF($C34<>1,"",IF(COUNT(AE34:AF34)<2,"",AVERAGE(AE34:AF34))) | AW34: =IF($C34<>1,"",IF(COUNT(AG34:AH34)<2,"",AVERAGE(AG34:AH34))) | AX34: =IF($C34<>1,"",IF(COUNT(AA34:AH34)<8,"",AVERAGE(AA34:AH34))) | AY34: =IF($C34<>1,"",IF(COUNT(AI34:AL34)<4,"",AVERAGE(AI34:AL34))) | AZ34: =IF($C34<>1,"",IF(OR(K34="",M34=""),"",IF(AND(OR(K34=3,K34=4),M34=3),1,0))) | BA34: 1
A35: R034 | B35: 35 | C35: 1 | D35: 1 | E35: 1 | F35: 58 | G35: 6 | H35: 2 | J35: 3 | K35: 4 | M35: 3 | N35: 1 | O35: 4 | P35: 4 | Q35: 4 | R35: 4 | S35: 4 | T35: 4 | U35: 4 | V35: 4 | W35: 2 | X35: 2 | Y35: 2 | Z35: 2 | AA35: 3 | AB35: 4 | AC35: 4 | AD35: 3 | AE35: 3 | AF35: 3 | AG35: 4 | AH35: 3 | AI35: 4 | AJ35: 4 | AK35: 4 | AL35: 4 | AM35: =IF(COUNT(O35:V35)<8,"",AVERAGE(O35:V35)) | AN35: =IF(COUNT(O35:O35)<1,"",AVERAGE(O35:O35)) | AO35: =IF(COUNT(P35:P35)<1,"",AVERAGE(P35:P35)) | AP35: =IF(COUNT(Q35:R35)<2,"",AVERAGE(Q35:R35)) | AQ35: =IF(COUNT(S35:T35)<2,"",AVERAGE(S35:T35)) | AR35: =IF(COUNT(U35:V35)<2,"",AVERAGE(U35:V35)) | AS35: =IF(COUNT(W35:Z35)<4,"",AVERAGE(W35:Z35)) | AT35: =IF($C35<>1,"",IF(COUNT(AA35:AB35)<2,"",AVERAGE(AA35:AB35))) | AU35: =IF($C35<>1,"",IF(COUNT(AC35:AD35)<2,"",AVERAGE(AC35:AD35))) | AV35: =IF($C35<>1,"",IF(COUNT(AE35:AF35)<2,"",AVERAGE(AE35:AF35))) | AW35: =IF($C35<>1,"",IF(COUNT(AG35:AH35)<2,"",AVERAGE(AG35:AH35))) | AX35: =IF($C35<>1,"",IF(COUNT(AA35:AH35)<8,"",AVERAGE(AA35:AH35))) | AY35: =IF($C35<>1,"",IF(COUNT(AI35:AL35)<4,"",AVERAGE(AI35:AL35))) | AZ35: =IF($C35<>1,"",IF(OR(K35="",M35=""),"",IF(AND(OR(K35=3,K35=4),M35=3),1,0))) | BA35: 1
A36: R035 | B36: 36 | C36: 1 | D36: 1 | E36: 1 | F36: 46 | G36: 20 | H36: 3 | J36: 4 | K36: 2 | M36: 2 | N36: 2 | O36: 4 | P36: 4 | Q36: 3 | R36: 3 | S36: 3 | T36: 4 | U36: 4 | V36: 4 | W36: 4 | X36: 4 | Y36: 4 | Z36: 4 | AA36: 3 | AB36: 3 | AC36: 4 | AD36: 3 | AE36: 3 | AF36: 4 | AG36: 5 | AH36: 3 | AI36: 1 | AJ36: 2 | AK36: 4 | AL36: 5 | AM36: =IF(COUNT(O36:V36)<8,"",AVERAGE(O36:V36)) | AN36: =IF(COUNT(O36:O36)<1,"",AVERAGE(O36:O36)) | AO36: =IF(COUNT(P36:P36)<1,"",AVERAGE(P36:P36)) | AP36: =IF(COUNT(Q36:R36)<2,"",AVERAGE(Q36:R36)) | AQ36: =IF(COUNT(S36:T36)<2,"",AVERAGE(S36:T36)) | AR36: =IF(COUNT(U36:V36)<2,"",AVERAGE(U36:V36)) | AS36: =IF(COUNT(W36:Z36)<4,"",AVERAGE(W36:Z36)) | AT36: =IF($C36<>1,"",IF(COUNT(AA36:AB36)<2,"",AVERAGE(AA36:AB36))) | AU36: =IF($C36<>1,"",IF(COUNT(AC36:AD36)<2,"",AVERAGE(AC36:AD36))) | AV36: =IF($C36<>1,"",IF(COUNT(AE36:AF36)<2,"",AVERAGE(AE36:AF36))) | AW36: =IF($C36<>1,"",IF(COUNT(AG36:AH36)<2,"",AVERAGE(AG36:AH36))) | AX36: =IF($C36<>1,"",IF(COUNT(AA36:AH36)<8,"",AVERAGE(AA36:AH36))) | AY36: =IF($C36<>1,"",IF(COUNT(AI36:AL36)<4,"",AVERAGE(AI36:AL36))) | AZ36: =IF($C36<>1,"",IF(OR(K36="",M36=""),"",IF(AND(OR(K36=3,K36=4),M36=3),1,0))) | BA36: 1
A37: R036 | B37: 37 | C37: 0 | D37: 2 | E37: 1 | F37: 60 | G37: 36 | H37: 1 | J37: 4 | K37: 2 | M37: 2 | N37: 2 | O37: 3 | P37: 3 | Q37: 2 | R37: 3 | S37: 2 | T37: 2 | U37: 3 | V37: 3 | W37: 2 | X37: 2 | Y37: 3 | Z37: 2 | AM37: =IF(COUNT(O37:V37)<8,"",AVERAGE(O37:V37)) | AN37: =IF(COUNT(O37:O37)<1,"",AVERAGE(O37:O37)) | AO37: =IF(COUNT(P37:P37)<1,"",AVERAGE(P37:P37)) | AP37: =IF(COUNT(Q37:R37)<2,"",AVERAGE(Q37:R37)) | AQ37: =IF(COUNT(S37:T37)<2,"",AVERAGE(S37:T37)) | AR37: =IF(COUNT(U37:V37)<2,"",AVERAGE(U37:V37)) | AS37: =IF(COUNT(W37:Z37)<4,"",AVERAGE(W37:Z37)) | AT37: =IF($C37<>1,"",IF(COUNT(AA37:AB37)<2,"",AVERAGE(AA37:AB37))) | AU37: =IF($C37<>1,"",IF(COUNT(AC37:AD37)<2,"",AVERAGE(AC37:AD37))) | AV37: =IF($C37<>1,"",IF(COUNT(AE37:AF37)<2,"",AVERAGE(AE37:AF37))) | AW37: =IF($C37<>1,"",IF(COUNT(AG37:AH37)<2,"",AVERAGE(AG37:AH37))) | AX37: =IF($C37<>1,"",IF(COUNT(AA37:AH37)<8,"",AVERAGE(AA37:AH37))) | AY37: =IF($C37<>1,"",IF(COUNT(AI37:AL37)<4,"",AVERAGE(AI37:AL37))) | AZ37: =IF($C37<>1,"",IF(OR(K37="",M37=""),"",IF(AND(OR(K37=3,K37=4),M37=3),1,0))) | BA37: 1
A38: R037 | B38: 38 | C38: 1 | D38: 2 | E38: 1 | F38: 56 | G38: 30 | H38: 4 | I38: 사업관리(부장) | J38: 3 | K38: 4 | M38: 3 | N38: 1 | O38: 3 | P38: 5 | Q38: 3 | R38: 5 | S38: 4 | T38: 3 | U38: 5 | V38: 5 | W38: 2 | X38: 2 | Y38: 2 | Z38: 4 | AA38: 4 | AB38: 4 | AC38: 4 | AD38: 4 | AE38: 4 | AF38: 3 | AG38: 5 | AH38: 5 | AI38: 5 | AJ38: 5 | AK38: 5 | AL38: 5 | AM38: =IF(COUNT(O38:V38)<8,"",AVERAGE(O38:V38)) | AN38: =IF(COUNT(O38:O38)<1,"",AVERAGE(O38:O38)) | AO38: =IF(COUNT(P38:P38)<1,"",AVERAGE(P38:P38)) | AP38: =IF(COUNT(Q38:R38)<2,"",AVERAGE(Q38:R38)) | AQ38: =IF(COUNT(S38:T38)<2,"",AVERAGE(S38:T38)) | AR38: =IF(COUNT(U38:V38)<2,"",AVERAGE(U38:V38)) | AS38: =IF(COUNT(W38:Z38)<4,"",AVERAGE(W38:Z38)) | AT38: =IF($C38<>1,"",IF(COUNT(AA38:AB38)<2,"",AVERAGE(AA38:AB38))) | AU38: =IF($C38<>1,"",IF(COUNT(AC38:AD38)<2,"",AVERAGE(AC38:AD38))) | AV38: =IF($C38<>1,"",IF(COUNT(AE38:AF38)<2,"",AVERAGE(AE38:AF38))) | AW38: =IF($C38<>1,"",IF(COUNT(AG38:AH38)<2,"",AVERAGE(AG38:AH38))) | AX38: =IF($C38<>1,"",IF(COUNT(AA38:AH38)<8,"",AVERAGE(AA38:AH38))) | AY38: =IF($C38<>1,"",IF(COUNT(AI38:AL38)<4,"",AVERAGE(AI38:AL38))) | AZ38: =IF($C38<>1,"",IF(OR(K38="",M38=""),"",IF(AND(OR(K38=3,K38=4),M38=3),1,0))) | BA38: 1
